Workbook

Sheet DASHBOARD
A1: AVENUE SUPERMART Financial Model & Valuation
D2: CONTENTS | F2: Current trading price | I2: 3751
D3: >>> Assumption | F3: Valuation
D4: >>> Income statement | F4: DCF | I4: 459
D5: >>> Balance sheet | F5: Residual income | I5: 1059
D6: >>> Cash flow statement | F6: Price to book | I6: 3468.1 To 4130.3
D7: >>> DCF | F7: Price to sales | I7: 3325.1 To 4670.9
D8: >>> Residual income | F8: Composite value | I8: ='Relative valuation'!I25 -> 2039.9339
D9: >>> Relative valuation
D10: >>> Ratio analysis | F10: DECISION | I10: =IF(I2<I8,"BUY","SELL") -> SELL
D11: >>> Charts | J11: Tolerance limit | L11: 0.1
A12: OVERVIEW
A13: DMart Ltd., headquartered in Mumbai, is a leading Indian retail chain known for its innovative store formats and extensive product offerings across food,
A14: general merchandise, and home solutions categories. With a focus on providing quality products at affordable prices, DMart has established a strong presence
A15: throughout India, offering customers a unique shopping experience.

Sheet Assumptions
N1: DASHBOARD
A2: FONT
B3: all hardcoded values are in blue
B4: all formulas and calculated values are in black
B5: all numbers are rounded off
A7: INCOME STATEMENT
A8: Income
A9: Revenue from operations | B9: revenue calculated with multiple approach such as revenue per store,average bill cuts and revenue per business. Further from 2027 sales grow at 15% to account for same level
A10: Other income | B10: Assumed to be in line with year average share of previous year
A11: Cost of Good Sold | B11: Assuming COGS ratio to be consistent with average of previous years
A12: Purchase of stock-in-trade
A13: Changes in inventories of stock-in-trade
A14: Gross Profit
A15: Other operating costs
A16: Employee benefits expense | B16: Assuming COGS ratio to be consistent with average of previous years
A17: Other expenses | B17: Assumed to be in line with average percent of income
A18: Operating Profit (EBITDA)
A19: Depreciation and amortisation expense | B19: Depreciation is taken as percentage of gross block | K19: =BS!H98 -> 0.034390135
A20: Operating Profit (EBIT)
A21: Finance costs | B21: Assumed to be in line with 2023 numbers
A22: Other non operating income
A25: Earnings before tax (EBT)
A26: Taxes | B26: Tax rate is taken to stay constant in the coming years | K26: 0.25
A27: Earning after taxes (EAT)
A28: Dividend paid | B28: Assumed to be zero as firm is not expected to pay any dividends
A29: Earnings transferred to reserve | B29: Assumed to be used the earning to finance, expansion activities.
A30: Profit for the parent
A31: Non-controlling interest | B31: Assumed to be zero
A33: Balance Sheet
A35: Total Assets
A36: Current Assets
A37: Cash and Cash equivalents | B37: Cash and Cash Equivalents is collected from corresponsing Cash Flow Statements
A38: Investment | B38: Assumed to be in line with 2023 numbers and taken to be constant in coming years
A39: Trade receivables | B39: Trade Receviables are forecast based on average receviable days
A40: Inventory | B40: Inventory is forecast based on Average Days Sale outstanding of preceding years.
A41: Other current assets | B41: Assumed to be in line with 2024 numbers and taken to be constant in coming years
A42: Long Term Assets
A43: PPE | B43: Take opening balance of PPE,add related capital expense and subtract depreciation.
A44: Capital work in progress | B44: Assumed to be in line with 2023 numbers and taken to be constant in coming years
A45: Right to use assets | B45: Assumed to be in line with 2023 numbers and taken to be constant in coming years
...

Sheet Sales
D2: 2019 | E2: 2020 | F2: 2021 | G2: 2022 | H2: 2023 | I2: 2024 | J2: 2025 | K2: rate | M2: DASHBOARD
C3: Revenue | D3: 20004.52 | E3: 24870.2 | F3: 24143.06 | G3: 30976.27 | H3: 42839.56 | I3: =I4*I5 -> 51823.199 | J3: =J4*J5 -> 62690.746 | K3: =RATE(4,0,-D3,H3,0,0) -> 0.20970428
C4: no of stores | D4: 176 | E4: 214 | F4: 234 | G4: 284 | H4: 324 | I4: =H4*$K$4+H4 -> 377.40104 | J4: =I4*$K$4+I4 -> 439.60354 | K4: =RATE(4,0,-D4,H4,0,0) -> 0.16481803
C5: Revenue per store | D5: =D3/D4 -> 113.66205 | E5: =E3/E4 -> 116.21589 | F5: =F3/F4 -> 103.17547 | G5: =G3/G4 -> 109.07137 | H5: =H3/H4 -> 132.22086 | I5: =H5*(1+$K$5) -> 137.31599 | J5: =I5*(1+$K$5) -> 142.60746 | K5: =RATE(4,0,-D5,H5,0,0) -> 0.038534985
E6: =E4-D4 -> 38 | F6: =F4-E4 -> 20 | G6: =G4-F4 -> 50 | H6: =H4-G4 -> 40
C7: bill cuts | D7: 17.2 | E7: 20.1 | F7: 15.2 | G7: 18.1 | H7: 25.8 | I7: =H7*(1+$K$7) -> 28.552394 | J7: =I7*(1+$K$7) -> 31.598418 | K7: =RATE(4,0,-D7,H7,0,0) -> 0.10668192
C8: Average bill count | D8: =D3/D7 -> 1163.0535 | E8: =E3/E7 -> 1237.3234 | F8: =F3/F7 -> 1588.3592 | G8: =G3/G7 -> 1711.3961 | H8: =H3/H7 -> 1660.4481 | I8: =I3/I7 -> 1815.0212 | J8: =J3/J7 -> 1983.9837 | K8: =RATE(4,0,-D8,H8,0,0) -> 0.09309121
I9: =I8*I7 -> 51823.199 | J9: =J8*J7 -> 62690.746
C11: retail business area | D11: 0.59 | E11: 0.78 | F11: 0.88 | G11: 1.15 | H11: 1.34 | I11: =H11*(1+$K$11) -> 1.6450079 | J11: =I11*(1+$K$11) -> 2.0194411 | K11: =RATE(4,0,-D11,H11,0,0) -> 0.22761786
C12: Revenue per business | D12: =D3/D11 -> 33905.966 | E12: =E3/E11 -> 31884.872 | F12: =F3/F11 -> 27435.295 | G12: =G3/G11 -> 26935.887 | H12: =H3/H11 -> 31969.821 | I12: =H12*(1+$K$12) -> 31503.313 | J12: =I12*(1+$K$12) -> 31043.612 | K12: =RATE(4,0,-D12,H12,0,0) -> -0.014592145
I13: =I12*I11 -> 51823.199 | J13: =J12*J11 -> 62690.746

Sheet IS
B1: INCOME STATEMENT | M1: DASHBOARD
B2: All amounts are in crores | C2: 2019A | D2: 2020A | E2: 2021A | F2: 2022A | G2: 2023A | H2: 2024E | I2: 2025E | J2: 2026E | K2: 2027E | L2: 2028E | O2: common size statements horizontol | P2: 2019A | Q2: 2020A | R2: 2021A | S2: 2022A | T2: 2023A | U2: Average
B3: Income | C3: =C4+C5 -> 20052.87 | D3: =D4+D5 -> 24930.19 | E3: =E4+E5 -> 24339.27 | F3: =F4+F5 -> 31093.76 | G3: =G4+G5 -> 42968.9 | H3: =H4+H5 -> 52027.851 | I3: =I4+I5 -> 62938.314 | J3: =J4+J5 -> 72379.061 | ... L3: =L4+L5 -> 95721.309 | O3: Income | Q3: =IFERROR((D3/C3)-1,"-") -> 0.24322304 | R3: =IFERROR((E3/D3)-1,"-") -> -0.023702988 | S3: =IFERROR((F3/E3)-1,"-") -> 0.27751407 | T3: =IFERROR((G3/F3)-1,"-") -> 0.38191393 | U3: =RATE(4,0,-C3,G3,0) -> 0.20988592
B4: revenue from operations | C4: 20004.52 | D4: 24870.2 | E4: 24143.06 | F4: 30976.27 | G4: 42839.56 | H4: =Sales!I3 -> 51823.199 | I4: =Sales!J3 -> 62690.746 | J4: =I4*1.15 -> 72094.357 | K4: =J4*1.15 -> 82908.511 | L4: =K4*1.15 -> 95344.788 | O4: revenue from operations | Q4: =IFERROR((D4/C4)-1,"-") -> 0.24322903 | R4: =IFERROR((E4/D4)-1,"-") -> -0.029237401 | S4: =IFERROR((F4/E4)-1,"-") -> 0.28302999 | T4: =IFERROR((G4/F4)-1,"-") -> 0.38297994 | U4: =IFERROR(RATE(4,0,-C4,G4,0),"-") -> 0.20970428
B5: other income | C5: 48.35 | D5: 59.99 | E5: 196.21 | F5: 117.49 | G5: 129.34 | H5: =H4*$H$30/$H$29 -> 204.65217 | I5: =I4*$H$30/$H$29 -> 247.5686 | J5: =J4*$H$30/$H$29 -> 284.70389 | K5: =K4*$H$30/$H$29 -> 327.40948 | L5: =L4*$H$30/$H$29 -> 376.5209 | O5: other income | Q5: =IFERROR((D5/C5)-1,"-") -> 0.24074457 | R5: =IFERROR((E5/D5)-1,"-") -> 2.2707118 | S5: =IFERROR((F5/E5)-1,"-") -> -0.40120279 | T5: =IFERROR((G5/F5)-1,"-") -> 0.10085965 | U5: =IFERROR(RATE(4,0,-C5,G5,0),"-") -> 0.27889266
B6: Cost of goods sold | C6: =C7+C8 -> 17000.84 | D6: =D7+D8 -> 21102.93 | E6: =E7+E8 -> 20554.68 | F6: =F7+F8 -> 26397.39 | G6: =G7+G8 -> 36383.95 | H6: =H3*$H$31 -> 44062.391 | I6: =I3*$H$31 -> 53302.463 | J6: =J3*$H$31 -> 61297.833 | K6: =K3*$H$31 -> 70492.508 | L6: =L3*$H$31 -> 81066.384 | O6: Cost of goods sold | Q6: =IFERROR((D6/C6)-1,"-") -> 0.24128749 | R6: =IFERROR((E6/D6)-1,"-") -> -0.025979805 | S6: =IFERROR((F6/E6)-1,"-") -> 0.28425205 | T6: =IFERROR((G6/F6)-1,"-") -> 0.37831619 | U6: =IFERROR(RATE(4,0,-C6,G6,0),"-") -> 0.20951112
B7: purchase of stock in trade | C7: 17445.49 | D7: 21441.68 | E7: 20855.56 | F7: 26891.77 | G7: 36884.77 | O7: purchase of stock in trade | Q7: =IFERROR((D7/C7)-1,"-") -> 0.22906723 | R7: =IFERROR((E7/D7)-1,"-") -> -0.027335545 | S7: =IFERROR((F7/E7)-1,"-") -> 0.28942929 | T7: =IFERROR((G7/F7)-1,"-") -> 0.37160068 | U7: =IFERROR(RATE(4,0,-C7,G7,0),"-") -> 0.20584358
B8: changes in inventory and stock in trade | C8: -444.65 | D8: -338.75 | E8: -300.88 | F8: -494.38 | G8: -500.82 | O8: changes in inventory and stock in trade | Q8: =IFERROR((D8/C8)-1,"-") -> -0.23816485 | R8: =IFERROR((E8/D8)-1,"-") -> -0.11179336 | S8: =IFERROR((F8/E8)-1,"-") -> 0.64311353 | T8: =IFERROR((G8/F8)-1,"-") -> 0.013026417 | U8: =IFERROR(RATE(4,0,-C8,G8,0),"-") -> 0.03018647
B9: Gross Profit | C9: =C3-C6 -> 3052.03 | D9: =D3-D6 -> 3827.26 | E9: =E3-E6 -> 3784.59 | F9: =F3-F6 -> 4696.37 | G9: =G3-G6 -> 6584.95 | H9: =H3-H6 -> 7965.4599 | I9: =I3-I6 -> 9635.8509 | J9: =J3-J6 -> 11081.229 | ... L9: =L3-L6 -> 14654.925 | O9: Gross Profit | Q9: =IFERROR((D9/C9)-1,"-") -> 0.25400471 | R9: =IFERROR((E9/D9)-1,"-") -> -0.011148968 | S9: =IFERROR((F9/E9)-1,"-") -> 0.2409191 | T9: =IFERROR((G9/F9)-1,"-") -> 0.40213612 | U9: =IFERROR(RATE(4,0,-C9,G9,0),"-") -> 0.21196735
B10: Other operating cost | C10: =SUM(C11:C12) -> 1370.39 | D10: =SUM(D11:D12) -> 1638.96 | E10: =SUM(E11:E12) -> 1845.33 | F10: =SUM(F11:F12) -> 2080.38 | G10: =SUM(G11:G12) -> 2818.58 | H10: =SUM(H11:H12) -> 3562.8703 | I10: =SUM(I11:I12) -> 4310.0194 | J10: =SUM(J11:J12) -> 4956.5224 | ... L10: =SUM(L11:L12) -> 6555.0008 | O10: Other operating cost | Q10: =IFERROR((D10/C10)-1,"-") -> 0.19598071 | R10: =IFERROR((E10/D10)-1,"-") -> 0.12591521 | S10: =IFERROR((F10/E10)-1,"-") -> 0.12737559 | T10: =IFERROR((G10/F10)-1,"-") -> 0.35483902 | U10: =IFERROR(RATE(4,0,-C10,G10,0),"-") -> 0.19755797
B11: employee benefit expense | C11: 355.42 | D11: 456.1 | E11: 536.57 | F11: 616.21 | G11: 746.97 | H11: =H3*$H$36 -> 991.30172 | I11: =I3*$H$36 -> 1199.1819 | J11: =J3*$H$36 -> 1379.0592 | K11: =K3*$H$36 -> 1585.9181 | L11: =L3*$H$36 -> 1823.8058 | O11: employee benefit expense | Q11: =IFERROR((D11/C11)-1,"-") -> 0.2832705 | R11: =IFERROR((E11/D11)-1,"-") -> 0.17643061 | S11: =IFERROR((F11/E11)-1,"-") -> 0.14842425 | T11: =IFERROR((G11/F11)-1,"-") -> 0.21220039 | U11: =IFERROR(RATE(4,0,-C11,G11,0),"-") -> 0.20403836
B12: other expense | C12: 1014.97 | D12: 1182.86 | E12: 1308.76 | F12: 1464.17 | G12: 2071.61 | H12: =H3*$H$37 -> 2571.5686 | I12: =I3*$H$37 -> 3110.8375 | J12: =J3*$H$37 -> 3577.4631 | K12: =K3*$H$37 -> 4114.0826 | L12: =L3*$H$37 -> 4731.195 | O12: other expense | Q12: =IFERROR((D12/C12)-1,"-") -> 0.16541376 | R12: =IFERROR((E12/D12)-1,"-") -> 0.10643694 | S12: =IFERROR((F12/E12)-1,"-") -> 0.11874599 | T12: =IFERROR((G12/F12)-1,"-") -> 0.41486986 | U12: =IFERROR(RATE(4,0,-C12,G12,0),"-") -> 0.19526361
B13: operating profit (EBITDA) | C13: =C9-C10 -> 1681.64 | D13: =D9-D10 -> 2188.3 | E13: =E9-E10 -> 1939.26 | F13: =F9-F10 -> 2615.99 | G13: =G9-G10 -> 3766.37 | H13: =H9-H10 -> 4402.5896 | I13: =I9-I10 -> 5325.8315 | J13: =J9-J10 -> 6124.7062 | ... L13: =L9-L10 -> 8099.924 | O13: operating profit (EBITDA) | Q13: =IFERROR((D13/C13)-1,"-") -> 0.30128922 | R13: =IFERROR((E13/D13)-1,"-") -> -0.11380524 | S13: =IFERROR((F13/E13)-1,"-") -> 0.34896301 | T13: =IFERROR((G13/F13)-1,"-") -> 0.43974939 | U13: =IFERROR(RATE(4,0,-C13,G13,0),"-") -> 0.22334088
B14: Depreciation and ammortization expense | C14: 212.49 | D14: 374.41 | E14: 414.16 | F14: 498.08 | G14: 638.87 | H14: =BS!H88 -> 481.27838 | I14: =BS!I88 -> 600.2854 | J14: =BS!J88 -> 719.03277 | K14: =BS!K88 -> 825.71108 | L14: =BS!L88 -> 866.54625 | O14: Depreciation and ammortization expense | Q14: =IFERROR((D14/C14)-1,"-") -> 0.76201233 | R14: =IFERROR((E14/D14)-1,"-") -> 0.10616704 | S14: =IFERROR((F14/E14)-1,"-") -> 0.202627 | T14: =IFERROR((G14/F14)-1,"-") -> 0.28266544 | U14: =IFERROR(RATE(4,0,-C14,G14,0),"-") -> 0.316796
B15: Operating profit (EBIT) | C15: =C13-C14 -> 1469.15 | D15: =D13-D14 -> 1813.89 | E15: =E13-E14 -> 1525.1 | F15: =F13-F14 -> 2117.91 | G15: =G13-G14 -> 3127.5 | H15: =H13-H14 -> 3921.3112 | I15: =I13-I14 -> 4725.5461 | J15: =J13-J14 -> 5405.6734 | ... L15: =L13-L14 -> 7233.3777 | O15: Operating profit (EBIT) | Q15: =IFERROR((D15/C15)-1,"-") -> 0.23465269 | R15: =IFERROR((E15/D15)-1,"-") -> -0.15921032 | S15: =IFERROR((F15/E15)-1,"-") -> 0.38870238 | T15: =IFERROR((G15/F15)-1,"-") -> 0.47669164 | U15: =IFERROR(RATE(4,0,-C15,G15,0),"-") -> 0.20790504
B16: Finance cost | C16: 47.21 | D16: 69.12 | E16: 41.65 | F16: 53.79 | G16: 67.41 | H16: =G16 -> 67.41 | I16: =H16 -> 67.41 | J16: =I16 -> 67.41 | K16: =J16 -> 67.41 | L16: =K16 -> 67.41 | O16: Finance cost | Q16: =IFERROR((D16/C16)-1,"-") -> 0.46409659 | R16: =IFERROR((E16/D16)-1,"-") -> -0.39742477 | S16: =IFERROR((F16/E16)-1,"-") -> 0.29147659 | T16: =IFERROR((G16/F16)-1,"-") -> 0.25320692 | U16: =IFERROR(RATE(4,0,-C16,G16,0),"-") -> 0.093131934
B17: Earnings before tax (EBT) | C17: =C15-C16 -> 1421.94 | D17: =D15-D16 -> 1744.77 | E17: =E15-E16 -> 1483.45 | F17: =F15-F16 -> 2064.12 | G17: =G15-G16 -> 3060.09 | H17: =H15-H16 -> 3853.9012 | I17: =I15-I16 -> 4658.1361 | J17: =J15-J16 -> 5338.2634 | ... L17: =L15-L16 -> 7165.9677 | O17: Earnings before tax (EBT) | Q17: =IFERROR((D17/C17)-1,"-") -> 0.2270349 | R17: =IFERROR((E17/D17)-1,"-") -> -0.14977332 | S17: =IFERROR((F17/E17)-1,"-") -> 0.39143213 | T17: =IFERROR((G17/F17)-1,"-") -> 0.48251555 | U17: =IFERROR(RATE(4,0,-C17,G17,0),"-") -> 0.21119267
B18: Taxes | C18: 519.48 | D18: 443.79 | E18: 384.02 | F18: 571.72 | G18: 681.75 | H18: =H17*25% -> 963.47531 | I18: =I17*25% -> 1164.534 | J18: =J17*25% -> 1334.5659 | K18: =K17*25% -> 1537.5728 | L18: =L17*25% -> 1791.4919 | O18: Taxes | Q18: =IFERROR((D18/C18)-1,"-") -> -0.1457034 | R18: =IFERROR((E18/D18)-1,"-") -> -0.13468082 | S18: =IFERROR((F18/E18)-1,"-") -> 0.48877663 | T18: =IFERROR((G18/F18)-1,"-") -> 0.19245435 | U18: =IFERROR(RATE(4,0,-C18,G18,0),"-") -> 0.070321079
B19: Earnings after tax (EAT) | C19: =C17-C18 -> 902.46 | D19: =D17-D18 -> 1300.98 | E19: =E17-E18 -> 1099.43 | F19: =F17-F18 -> 1492.4 | G19: =G17-G18 -> 2378.34 | H19: =H17-H18 -> 2890.4259 | I19: =I17-I18 -> 3493.6021 | J19: =J17-J18 -> 4003.6976 | ... L19: =L17-L18 -> 5374.4758 | O19: Earnings after tax (EAT) | Q19: =IFERROR((D19/C19)-1,"-") -> 0.44159298 | R19: =IFERROR((E19/D19)-1,"-") -> -0.15492167 | S19: =IFERROR((F19/E19)-1,"-") -> 0.35743067 | T19: =IFERROR((G19/F19)-1,"-") -> 0.59363441 | U19: =IFERROR(RATE(4,0,-C19,G19,0),"-") -> 0.27412341
B20: dividends | C20: 0 | D20: 0 | E20: 0 | F20: 0 | G20: 0 | H20: 0 | I20: 0 | J20: 0 | K20: 0 | L20: 0 | O20: dividends | Q20: =IFERROR((D20/C20)-1,"-") -> - | R20: =IFERROR((E20/D20)-1,"-") -> - | S20: =IFERROR((F20/E20)-1,"-") -> - | T20: =IFERROR((G20/F20)-1,"-") -> - | U20: =IFERROR(RATE(4,0,-C20,G20,0),"-") -> -
B21: Earnings transferred to reserve | C21: =C19-C20 -> 902.46 | D21: =D19-D20 -> 1300.98 | E21: =E19-E20 -> 1099.43 | F21: =F19-F20 -> 1492.4 | G21: =G19-G20 -> 2378.34 | H21: =H19-H20 -> 2890.4259 | I21: =I19-I20 -> 3493.6021 | J21: =J19-J20 -> 4003.6976 | ... L21: =L19-L20 -> 5374.4758 | O21: Earnings transferred to reserve | Q21: =IFERROR((D21/C21)-1,"-") -> 0.44159298 | R21: =IFERROR((E21/D21)-1,"-") -> -0.15492167 | S21: =IFERROR((F21/E21)-1,"-") -> 0.35743067 | T21: =IFERROR((G21/F21)-1,"-") -> 0.59363441 | U21: =IFERROR(RATE(4,0,-C21,G21,0),"-") -> 0.27412341
B22: profit for the parent
B23: Non controlling interest
H24: AVERAGE
B25: TAX RATE | C25: =C18/C17 -> 0.36533187 | D25: =D18/D17 -> 0.25435444 | E25: =E18/E17 -> 0.25886953 | F25: =F18/F17 -> 0.27698002 | G25: =G18/G17 -> 0.22278757
B26: COST OF DEBT | C26: =C16/C15 -> 0.032134227 | D26: =D16/D15 -> 0.038105949 | E26: =E16/E15 -> 0.027309685 | F26: =F16/F15 -> 0.02539768 | G26: =G16/G15 -> 0.021553957 | H26: =AVERAGE(C26:G26) -> 0.0289003
B27: common size statement vertical | C27: 2019A | D27: 2020A | E27: 2021A | F27: 2022A | G27: 2023A | H27: Average
B28: Income | C28: =C3/C$3 -> 1 | D28: =D3/D$3 -> 1 | E28: =E3/E$3 -> 1 | F28: =F3/F$3 -> 1 | G28: =G3/G$3 -> 1 | H28: =AVERAGE(C28:G28) -> 1
B29: revenue from operations | C29: =C4/C$3 -> 0.99758887 | D29: =D4/D$3 -> 0.99759368 | E29: =E4/E$3 -> 0.99193854 | F29: =F4/F$3 -> 0.99622143 | G29: =G4/G$3 -> 0.99698992 | H29: =AVERAGE(C29:G29) -> 0.99606649
B30: other income | C30: =C5/C$3 -> 0.0024111262 | D30: =D5/D$3 -> 0.0024063194 | E30: =E5/E$3 -> 0.0080614579 | F30: =F5/F$3 -> 0.0037785716 | G30: =G5/G$3 -> 0.003010084 | H30: =AVERAGE(C30:G30) -> 0.0039335118
B31: Cost of goods sold | C31: =C6/C$3 -> 0.84780084 | D31: =D6/D$3 -> 0.84648091 | E31: =E6/E$3 -> 0.84450684 | F31: =F6/F$3 -> 0.84896101 | G31: =G6/G$3 -> 0.84675079 | H31: =AVERAGE(C31:G31) -> 0.84690008
B32: purchase of stock in trade | C32: =C7/C$3 -> 0.86997472 | D32: =D7/D$3 -> 0.86006886 | E32: =E7/E$3 -> 0.85686876 | F32: =F7/F$3 -> 0.86486067 | G32: =G7/G$3 -> 0.8584062 | H32: =AVERAGE(C32:G32) -> 0.86203584
B33: changes in inventory and stock in trade | C33: =C8/C$3 -> -0.022173883 | D33: =D8/D$3 -> -0.013587943 | E33: =E8/E$3 -> -0.012361916 | F33: =F8/F$3 -> -0.015899653 | G33: =G8/G$3 -> -0.011655407 | H33: =AVERAGE(C33:G33) -> -0.01513576
B34: Gross Profit | C34: =C9/C$3 -> 0.15219916 | D34: =D9/D$3 -> 0.15351909 | E34: =E9/E$3 -> 0.15549316 | F34: =F9/F$3 -> 0.15103899 | G34: =G9/G$3 -> 0.15324921 | H34: =AVERAGE(C34:G34) -> 0.15309992
B35: Other operating cost | C35: =C10/C$3 -> 0.068338846 | D35: =D10/D$3 -> 0.065741978 | E35: =E10/E$3 -> 0.075816982 | F35: =F10/F$3 -> 0.066906672 | G35: =G10/G$3 -> 0.065595815 | H35: =AVERAGE(C35:G35) -> 0.068480059
B36: employee benefit expense | C36: =C11/C$3 -> 0.017724146 | D36: =D11/D$3 -> 0.018295087 | E36: =E11/E$3 -> 0.022045443 | F36: =F11/F$3 -> 0.019817803 | G36: =G11/G$3 -> 0.017383968 | H36: =AVERAGE(C36:G36) -> 0.01905329
B37: other expense | C37: =C12/C$3 -> 0.0506147 | D37: =D12/D$3 -> 0.047446891 | E37: =E12/E$3 -> 0.053771539 | F37: =F12/F$3 -> 0.047088869 | G37: =G12/G$3 -> 0.048211846 | H37: =AVERAGE(C37:G37) -> 0.049426769
B38: operating profit (EBITDA) | C38: =C13/C$3 -> 0.083860315 | D38: =D13/D$3 -> 0.087777109 | E38: =E13/E$3 -> 0.079676178 | F38: =F13/F$3 -> 0.084132315 | G38: =G13/G$3 -> 0.087653396 | H38: =AVERAGE(C38:G38) -> 0.084619862
B39: Depreciation and ammortization expense | C39: =C14/C$3 -> 0.010596488 | D39: =D14/D$3 -> 0.015018337 | E39: =E14/E$3 -> 0.017016123 | F39: =F14/F$3 -> 0.016018648 | G39: =G14/G$3 -> 0.014868195 | H39: =AVERAGE(C39:G39) -> 0.014703558
... B48: Non controlling interest | C48: =C23/C$3 -> 0 | D48: =D23/D$3 -> 0 | E48: =E23/E$3 -> 0 | F48: =F23/F$3 -> 0 | G48: =G23/G$3 -> 0 | H48: =AVERAGE(C48:G48) -> 0

Sheet BS
B2: All amounts are in crores | C2: 2019A | D2: 2020A | E2: 2021A | F2: 2022A | G2: 2023A | H2: 2024E | I2: 2025E | J2: 2026E | K2: 2027E | L2: 2028E | N2: DASHBOARD
B3: TOTAL ASSETS | C3: =C4+C11 -> 7005.72 | D3: =D4+D11 -> 12076.45 | E3: =E4+E11 -> 13655.97 | F3: =F4+F11 -> 15472.64 | G3: =G4+G11 -> 18106.29 | H3: =H4+H11 -> 20980.4 | I3: =I4+I11 -> 23795.105 | J3: =J4+J11 -> 27727.962 | ... L3: =L4+L11 -> 36825.148
B4: Current assets | C4: =SUM(C5:C10) -> 2082.58 | D4: =SUM(D5:D10) -> 2347.67 | E4: =SUM(E5:E10) -> 4061.13 | F4: =SUM(F5:F10) -> 3442.85 | G4: =SUM(G5:G10) -> 5448.39 | H4: =SUM(H5:H10) -> 6407.8242 | I4: =SUM(I5:I10) -> 6362.3155 | J4: =SUM(J5:J10) -> 7561.2572 | ... L4: =SUM(L5:L10) -> 14061.288
B5: inventories | C5: 1608.65 | D5: 1947.4 | E5: 2248.28 | F5: 2742.66 | G5: 3243.48 | H5: =2*(IS!H6/'Ratio Analysis'!$E$32)-BS!G5 -> 4824.1025 | I5: =2*(IS!I6/'Ratio Analysis'!$E$32)-BS!H5 -> 4935.2866 | J5: =2*(IS!J6/'Ratio Analysis'!$E$32)-BS!I5 -> 6288.0109 | K5: =2*(IS!K6/'Ratio Analysis'!$E$32)-BS!J5 -> 6618.7812 | L5: =2*(IS!L6/'Ratio Analysis'!$E$32)-BS!K5 -> 8224.0297
B6: cash and cash equivalents | C6: =CF!C58+0.12 -> 124.98 | D6: =CF!D58+0.01 -> 105.87 | E6: =CF!E58 -> 191.5 | F6: =CF!F58 -> 95.12 | G6: =CF!G58 -> 207.15 | H6: =CF!H58-99.44 -> -486.75935 | I6: =CF!I58-482.98 -> -612.05144 | J6: =CF!J58-773.43 -> -832.98895 | K6: =CF!K58-1162.81 -> 568.49668 | L6: =CF!L58-1674.3-30.63 -> 3683.7377
B7: trade receivables | C7: 64.37 | D7: 19.55 | E7: 43.58 | F7: 66.89 | G7: 62.16 | H7: =2*(IS!H3/'Ratio Analysis'!$E$33)-G7 -> 134.8811 | I7: =2*(IS!I3/'Ratio Analysis'!$E$33)-H7 -> 103.48036 | J7: =2*(IS!J3/'Ratio Analysis'!$E$33)-I7 -> 170.63531 | K7: =2*(IS!K3/'Ratio Analysis'!$E$33)-J7 -> 144.59771 | L7: =2*(IS!L3/'Ratio Analysis'!$E$33)-K7 -> 217.92027
B8: investments | C8: 16.53 | D8: 14.68 | E8: 2.95 | F8: 5.93 | G8: 202.19 | H8: =G8 -> 202.19 | I8: =H8 -> 202.19 | J8: =I8 -> 202.19 | K8: =J8 -> 202.19 | L8: =K8 -> 202.19
B9: bank balance other than cash | C9: 94.09 | D9: 2.01 | E9: 1254.08 | F9: 203.46 | G9: 1201.18 | H9: =G9 -> 1201.18 | I9: =H9 -> 1201.18 | J9: =I9 -> 1201.18 | K9: =J9 -> 1201.18 | L9: =K9 -> 1201.18
B10: other current assets | C10: =59.1 + 114.86 -> 173.96 | D10: =109.06+149.1 -> 258.16 | E10: =167.91+152.83 -> 320.74 | F10: =127.46+201.33 -> 328.79 | G10: =316.77+215.46 -> 532.23 | H10: =G10 -> 532.23 | I10: =H10 -> 532.23 | J10: =I10 -> 532.23 | K10: =J10 -> 532.23 | L10: =K10 -> 532.23
B11: Long term assets | C11: =SUM(C12:C19) -> 4923.14 | D11: =SUM(D12:D19) -> 9728.78 | E11: =SUM(E12:E19) -> 9594.84 | F11: =SUM(F12:F19) -> 12029.79 | G11: =SUM(G12:G19) -> 12657.9 | H11: =SUM(H12:H19) -> 14572.576 | I11: =SUM(I12:I19) -> 17432.789 | J11: =SUM(J12:J19) -> 20166.705 | ... L11: =SUM(L12:L19) -> 22763.86
B12: PPE | C12: =C93 -> 4274.03 | D12: =D93 -> 5107.36 | E12: =E93 -> 5938.5 | F12: =F93 -> 7770.46 | G12: =G93 -> 9725.61 | H12: =H93 -> 11640.286 | I12: =I93 -> 14500.499 | J12: =J93 -> 17234.415 | ... L12: =L93 -> 19831.57
B13: capital work in progress | C13: 376.84 | D13: 364.4 | E13: 1019.59 | F13: 1129.34 | G13: 829.16 | H13: =G13 -> 829.16 | I13: =H13 -> 829.16 | J13: =I13 -> 829.16 | K13: =J13 -> 829.16 | L13: =K13 -> 829.16
B14: right of use assets | C14: 0 | D14: 717.33 | E14: 960.24 | F14: 1388.65 | G14: 1504.88 | H14: =G14 -> 1504.88 | I14: =H14 -> 1504.88 | J14: =I14 -> 1504.88 | K14: =J14 -> 1504.88 | L14: =K14 -> 1504.88
B15: Investment properties | C15: 18.1 | D15: 16.53 | E15: 9.57 | F15: 9.03 | G15: 8.54 | H15: =G15 -> 8.54 | I15: =H15 -> 8.54 | J15: =I15 -> 8.54 | K15: =J15 -> 8.54 | L15: =K15 -> 8.54
B16: Goodwill | C16: 78.27 | D16: 78.27 | E16: 78.27 | F16: 78.27 | G16: 78.27 | H16: =G16 -> 78.27 | I16: =H16 -> 78.27 | J16: =I16 -> 78.27 | K16: =J16 -> 78.27 | L16: =K16 -> 78.27
B17: Intangible assets | C17: 29.97 | D17: 28.54 | E17: 22.22 | F17: 13.61 | G17: 23.18 | H17: =G17 -> 23.18 | I17: =H17 -> 23.18 | J17: =I17 -> 23.18 | K17: =J17 -> 23.18 | L17: =K17 -> 23.18
B18: financial assets | C18: 31.74 | D18: 3122.67 | E18: 1109.28 | F18: =0.01+1262.7 -> 1262.71 | G18: =0.01+108.55 -> 108.56 | H18: =G18 -> 108.56 | I18: =H18 -> 108.56 | J18: =I18 -> 108.56 | K18: =J18 -> 108.56 | L18: =K18 -> 108.56
B19: other non current assets | C19: =0.64+0.22 +113.33 -> 114.19 | D19: =8.25+0.29+285.14 -> 293.68 | E19: =1.63+0.92+454.62 -> 457.17 | F19: =2.28+1.66+373.78 -> 377.72 | G19: =17.5+1.77+360.43 -> 379.7 | H19: =G19 -> 379.7 | I19: =H19 -> 379.7 | J19: =I19 -> 379.7 | K19: =J19 -> 379.7 | L19: =K19 -> 379.7
B21: TOTAL EXTERNAL LIABILITIES | C21: =C22+C33 -> 7005.72 | D21: =D22+D33 -> 12076.45 | E21: =E22+E33 -> 13655.97 | F21: =F22+F33 -> 15472.64 | G21: =G22+G33 -> 18106.29 | H21: =H22+H33 -> 20980.394 | I21: =I22+I33 -> 23795.103 | J21: =J22+J33 -> 27727.955 | ... L21: =L22+L33 -> 36825.142
B22: TOTAL LIABILITIES | C22: =C23+C28 -> 1417.71 | D22: =D23+D28 -> 996.25 | E22: =E23+E28 -> 1471.86 | F22: =F23+F28 -> 1794.75 | G22: =G23+G28 -> 2027.51 | H22: =H23+H28 -> 2523.354 | I22: =I23+I28 -> 2447.6366 | J22: =J23+J28 -> 2886.8866 | ... L22: =L23+L28 -> 3367.6585
B23: Current liabilities | C23: =SUM(C24:C27) -> 1226.92 | D23: =SUM(D24:D27) -> 725.8 | E23: =SUM(E24:E27) -> 1105.77 | F23: =SUM(F24:F27) -> 1218.29 | G23: =SUM(G24:G27) -> 1467.01 | H23: =SUM(H24:H27) -> 1962.854 | I23: =SUM(I24:I27) -> 1887.1366 | J23: =SUM(J24:J27) -> 2326.3866 | ... L23: =SUM(L24:L27) -> 2807.1585
B24: Short term borrowings | C24: 304.15 | D24: 3.73 | E24: 0 | F24: 0 | G24: 0 | H24: 0 | I24: 0 | J24: 0 | K24: 0 | L24: 0
B25: Lease liabilities | C25: 0 | D25: 74.35 | E25: 80.7 | F25: 139.79 | G25: 166.32 | H25: =G25 -> 166.32 | I25: =H25 -> 166.32 | J25: =I25 -> 166.32 | K25: =J25 -> 166.32 | L25: =K25 -> 166.32
B26: Trade payables | C26: =5.44 +457.83 -> 463.27 | D26: =17.47+415.98 -> 433.45 | E26: =21.95+556.18 -> 578.13 | F26: =32.39+556.81 -> 589.2 | G26: =76.29+677.5 -> 753.79 | H26: =2*(IS!H6/'Ratio Analysis'!$E$31)-G26 -> 1249.634 | I26: =2*(IS!I6/'Ratio Analysis'!$E$31)-H26 -> 1173.9166 | J26: =2*(IS!J6/'Ratio Analysis'!$E$31)-I26 -> 1613.1666 | K26: =2*(IS!K6/'Ratio Analysis'!$E$31)-J26 -> 1591.9791 | L26: =2*(IS!L6/'Ratio Analysis'!$E$31)-K26 -> 2093.9385
B27: other current liabilities | C27: =396.93+26.78+22.95 +12.84 -> 459.5 | D27: =177.94+0.45+20.7+15.18 -> 214.27 | E27: =269.78+112.66+40.73+23.77 -> 446.94 | F27: =282.92+58.37 +36.44 +111.57 -> 489.3 | G27: =289.46+121.18+50.87+85.39 -> 546.9 | H27: =G27 -> 546.9 | I27: =H27 -> 546.9 | J27: =I27 -> 546.9 | K27: =J27 -> 546.9 | L27: =K27 -> 546.9
B28: Long term liabilities | C28: =SUM(C29:C31) -> 190.79 | D28: =SUM(D29:D31) -> 270.45 | E28: =SUM(E29:E31) -> 366.09 | F28: =SUM(F29:F31) -> 576.46 | G28: =SUM(G30:G31) -> 560.5 | H28: =SUM(H29:H31) -> 560.5 | I28: =SUM(I29:I31) -> 560.5 | J28: =SUM(J29:J31) -> 560.5 | K28: =SUM(K29:K31) -> 560.5 | L28: =SUM(L29:L31) -> 560.5
B29: Long term borrowing | C29: 125.67 | D29: 0 | E29: 0 | F29: 0 | G29: 0 | H29: 0 | I29: 0 | J29: 0 | K29: 0 | L29: 0
B30: lease liabilities | C30: 0 | D30: 221.11 | E30: 312.01 | F30: 507.15 | G30: 476.66 | H30: =G30 -> 476.66 | I30: =H30 -> 476.66 | J30: =I30 -> 476.66 | K30: =J30 -> 476.66 | L30: =K30 -> 476.66
B31: other non current liabilities | C31: =0.78 +1.05 +63.29 -> 65.12 | D31: =0.47+1.48+47.39 -> 49.34 | E31: =0.44+2.45+51.19 -> 54.08 | F31: =0.41+4.87+64.03 -> 69.31 | G31: =0.47 +6.41+76.96 -> 83.84 | H31: =G31 -> 83.84 | I31: =H31 -> 83.84 | J31: =I31 -> 83.84 | K31: =J31 -> 83.84 | L31: =K31 -> 83.84
B33: EQUITIES | C33: =C34+C37 -> 5588.01 | D33: =D34+D37 -> 11080.2 | E33: =E34+E37 -> 12184.11 | F33: =F34+F37 -> 13677.89 | G33: =G34+G37 -> 16078.78 | H33: =H34+H37 -> 18457.04 | I33: =I34+I37 -> 21347.466 | J33: =J34+J37 -> 24841.068 | ... L33: =L34+L37 -> 33457.484
B34: shareholder equity | C34: =C35+C36 -> 5587.45 | D34: =D35+D36 -> 11079.74 | E34: =E35+E36 -> 12183.71 | F34: =F35+F36 -> 13677.64 | G34: =G35+G36 -> 16078.7 | H34: =H35+H36 -> 18457.04 | I34: =I35+I36 -> 21347.466 | J34: =J35+J36 -> 24841.068 | ... L34: =L35+L36 -> 33457.484
B35: equity share capital | C35: 624.08 | D35: 647.77 | E35: 647.77 | F35: 647.77 | G35: 648.26 | H35: =G35 -> 648.26 | I35: =H35 -> 648.26 | J35: =I35 -> 648.26 | K35: =J35 -> 648.26 | L35: =K35 -> 648.26
B36: other equity | C36: 4963.37 | D36: 10431.97 | E36: 11535.94 | F36: 13029.87 | G36: 15430.44 | H36: =G36+IS!G21 -> 17808.78 | I36: =H36+IS!H21 -> 20699.206 | J36: =I36+IS!I21 -> 24192.808 | K36: =J36+IS!J21 -> 28196.506 | L36: =K36+IS!K21 -> 32809.224
B37: non controlling interest | C37: 0.56 | D37: 0.46 | E37: 0.4 | F37: 0.25 | G37: 0.08 | H37: 0 | I37: 0 | J37: 0 | K37: 0 | L37: 0
B39: BALANCE SHEET CHECK | C39: =IF(C21=C3,TRUE,FALSE) -> TRUE | D39: =IF(D21=D3,TRUE,FALSE) -> TRUE | E39: =IF(E21=E3,TRUE,FALSE) -> TRUE | F39: =IF(F21=F3,TRUE,FALSE) -> TRUE | G39: =IF(G21=G3,TRUE,FALSE) -> TRUE | H39: =ROUND(H3,0)=ROUND(H21,0) -> TRUE | I39: =ROUND(I3,0)=ROUND(I21,0) -> TRUE | J39: =ROUND(J3,0)=ROUND(J21,0) -> TRUE | K39: =ROUND(K3,0)=ROUND(K21,0) -> TRUE | L39: =ROUND(L3,0)=ROUND(L21,0) -> TRUE
B41: Vertical analysis | C41: 2019A | D41: 2020A | E41: 2021A | F41: 2022A | G41: 2023A
B42: TOTAL ASSETS | C42: =IFERROR(C3/$C$3,"-") -> 1 | D42: =IFERROR(D3/$D$3,"-") -> 1 | E42: =IFERROR(E3/$E$3,"-") -> 1 | F42: =IFERROR(F3/$F$3,"-") -> 1 | G42: =IFERROR(G3/$G$3,"-") -> 1
B43: Current assets | C43: =IFERROR(C4/$C$3,"-") -> 0.29726852 | D43: =IFERROR(D4/$D$3,"-") -> 0.19440067 | E43: =IFERROR(E4/$E$3,"-") -> 0.29738861 | F43: =IFERROR(F4/$F$3,"-") -> 0.22251212 | G43: =IFERROR(G4/$G$3,"-") -> 0.30091145
B44: inventories | C44: =IFERROR(C5/$C$3,"-") -> 0.22961951 | D44: =IFERROR(D5/$D$3,"-") -> 0.161256 | E44: =IFERROR(E5/$E$3,"-") -> 0.16463715 | F44: =IFERROR(F5/$F$3,"-") -> 0.1772587 | G44: =IFERROR(G5/$G$3,"-") -> 0.17913554
B45: cash and cash equivalents | C45: =IFERROR(C6/$C$3,"-") -> 0.017839708 | D45: =IFERROR(D6/$D$3,"-") -> 0.0087666491 | E45: =IFERROR(E6/$E$3,"-") -> 0.014023171 | F45: =IFERROR(F6/$F$3,"-") -> 0.0061476257 | G45: =IFERROR(G6/$G$3,"-") -> 0.011440776
...

Sheet CF
B2: All amounts are in crores | C2: 2019A | D2: 2020A | E2: 2021A | F2: 2022A | G2: 2023A | H2: 2024E | I2: 2025E | J2: 2026E | K2: 2027E | L2: 2028E | N2: DASHBOARD
B3: Cash flow from operating activities | C3: =SUM(C4:C26) -> 806.84 | D3: =SUM(D4:D26) -> 1280.14 | E3: =SUM(E4:E26) -> 1375.14 | F3: =SUM(F4:F26) -> 1372.35 | G3: =SUM(G4:G26) -> 2630.27 | H3: =SUM(H4:H26) -> 2174.0547 | I3: =SUM(I4:I26) -> 3898.2367 | J3: =SUM(J4:J26) -> 3701.9511 | ... L3: =SUM(L4:L26) -> 5024.2604
B4: profit before tax | C4: =IS!C17 -> 1421.94 | D4: =IS!D17 -> 1744.77 | E4: =IS!E17 -> 1483.45 | F4: =IS!F17 -> 2064.12 | G4: =IS!G17 -> 3060.09 | H4: =IS!H17 -> 3853.9012 | I4: =IS!I17 -> 4658.1361 | J4: =IS!J17 -> 5338.2634 | ... L4: =IS!L17 -> 7165.9677
B5: depreciation and ammortization | C5: =IS!C14 -> 212.49 | D5: =IS!D14 -> 374.41 | E5: =IS!E14 -> 414.16 | F5: =IS!F14 -> 498.08 | G5: =IS!G14 -> 638.87 | H5: =IS!H14 -> 481.27838 | I5: =IS!I14 -> 600.2854 | J5: =IS!J14 -> 719.03277 | ... L5: =IS!L14 -> 866.54625
B6: Finance cost | C6: =IS!C16 -> 47.21 | D6: =IS!D16 -> 69.12 | E6: =IS!E16 -> 41.65 | F6: =IS!F16 -> 53.79 | G6: =IS!G16 -> 67.41 | H6: =IS!H16 -> 67.41 | I6: =IS!I16 -> 67.41 | J6: =IS!J16 -> 67.41 | ... L6: =IS!L16 -> 67.41
B7: Interest income | C7: -23.59 | D7: -32.49 | E7: -178.13 | F7: -103.96 | G7: -107.56 | H7: =G7 -> -107.56 | I7: =H7 -> -107.56 | J7: =I7 -> -107.56 | K7: =J7 -> -107.56 | L7: =K7 -> -107.56
B8: profit on sale of investment | C8: -11.35 | D8: -10.16 | E8: -2.56 | F8: -3.66 | G8: -8.83
B9: expense on employee stock option | C9: 17.15 | D9: 8.46 | E9: 6.38 | F9: 6.42 | G9: 12.01
B10: rent income | C10: -3.6 | D10: -2.88 | E10: -2.89 | F10: -3.55 | G10: -4.69
B11: loss on PPE | C11: -0.99 | D11: -2.45 | E11: 1.78 | F11: 3.85 | G11: 1.74
B12: Change in working capital
B13: change in trade payables | C13: 145.99 | D13: =BS!D26-BS!C26 -> -29.82 | E13: =BS!E26-BS!D26 -> 144.68 | F13: =BS!F26-BS!E26 -> 11.07 | G13: =BS!G26-BS!F26 -> 164.59 | H13: =BS!H26-BS!G26 -> 495.84402 | I13: =BS!I26-BS!H26 -> -75.717429 | J13: =BS!J26-BS!I26 -> 439.25002 | K13: =BS!K26-BS!J26 -> -21.18754 | L13: =BS!L26-BS!K26 -> 501.95939
B14: change in current provisions | C14: -1.15 | D14: -3.04 | E14: 6.24 | F14: 6.53 | G14: 7.99 | H14: 0 | I14: 0 | J14: 0 | K14: 0 | L14: 0
B15: change in other current financial liabilities | C15: -29.45 | D15: 24.28 | E15: 48.87 | F15: -6.91 | G15: -7.11 | H15: 0 | I15: 0 | J15: 0 | K15: 0 | L15: 0
B16: change in other current liabilities | C16: 10.45 | D16: -2.24 | E16: 20.03 | F16: 17.64 | G16: 62.81 | H16: 0 | I16: 0 | J16: 0 | K16: 0 | L16: 0
B17: change in non current provisions | C17: 0.31 | D17: 0.43 | E17: 0.97 | F17: 2.42 | G17: 1.54 | H17: 0 | I17: 0 | J17: 0 | K17: 0 | L17: 0
B18: change in other non current financial liabilities | C18: 0 | D18: -0.31 | E18: -0.03 | F18: -0.03 | G18: 0.06 | H18: 0 | I18: 0 | J18: 0 | K18: 0 | L18: 0
B19: change in trade receivables | C19: -30.87 | D19: =BS!C7-BS!D7 -> 44.82 | E19: =BS!D7-BS!E7 -> -24.03 | F19: =BS!E7-BS!F7 -> -23.31 | G19: =BS!F7-BS!G7 -> 4.73 | H19: =BS!G7-BS!H7 -> -72.721096 | I19: =BS!H7-BS!I7 -> 31.400735 | J19: =BS!I7-BS!J7 -> -67.154954 | K19: =BS!J7-BS!K7 -> 26.037602 | L19: =BS!K7-BS!L7 -> -73.322556
B20: change in inventories | C20: -445.2 | D20: =BS!C5-BS!D5 -> -338.75 | E20: =BS!D5-BS!E5 -> -300.88 | F20: =BS!E5-BS!F5 -> -494.38 | G20: =BS!F5-BS!G5 -> -500.82 | H20: =BS!G5-BS!H5 -> -1580.6225 | I20: =BS!H5-BS!I5 -> -111.18407 | J20: =BS!I5-BS!J5 -> -1352.7243 | K20: =BS!J5-BS!K5 -> -330.77032 | L20: =BS!K5-BS!L5 -> -1605.2485
B21: change in current investments | C21: 51.65 | D21: 1.85 | E21: 11.73 | F21: -2.98 | G21: 0 | H21: 0 | I21: 0 | J21: 0 | K21: 0 | L21: 0
B22: change in other non current financial assets | C22: 9.66 | D22: -11.33 | E22: -15.26 | F22: -6.79 | G22: -18.99 | H22: 0 | I22: 0 | J22: 0 | K22: 0 | L22: 0
B23: change in other current assets | C23: -67.18 | D23: -42.43 | E23: -4.79 | F23: -48.96 | G23: -48.71 | H23: 0 | I23: 0 | J23: 0 | K23: 0 | L23: 0
B24: change in other current financial assets | C24: 5.64 | D24: -19.2 | E24: -12.59 | F24: -37.41 | G24: 13.91 | H24: 0 | I24: 0 | J24: 0 | K24: 0 | L24: 0
B25: increase in bank balance other than cash | C25: -0.5 | D25: -0.5 | E25: -2.07 | F25: 0.62 | G25: 0.12 | H25: 0 | I25: 0 | J25: 0 | K25: 0 | L25: 0
B26: Direct tax paid | C26: -501.77 | D26: -492.4 | E26: -261.57 | F26: -560.25 | G26: -708.89 | H26: =-IS!H18 -> -963.47531 | I26: =-IS!I18 -> -1164.534 | J26: =-IS!J18 -> -1334.5659 | K26: =-IS!K18 -> -1537.5728 | L26: =-IS!L18 -> -1791.4919
B28: Cash flow from investing activities | C28: =SUM(C29:C36) -> -958.37 | D28: =SUM(D29:D36) -> -4656.56 | E28: =SUM(E29:E36) -> -1110 | F28: =SUM(F29:F36) -> -1289.49 | G28: =SUM(G29:G36) -> -2313.1 | H28: =SUM(H29:H36) -> -2481.4741 | I28: =SUM(I29:I36) -> -3352.9388 | J28: =SUM(J29:J36) -> -3345.3886 | ... L28: =SUM(L29:L36) -> -1079.8493
B29: Proceeds from disposal of property, plant and equipment | C29: 8.44 | D29: 6.15 | E29: 1.88 | F29: 20.92 | G29: 5.46 | H29: =BS!H83 -> 26.425931 | I29: =BS!I83 -> 38.167219 | J29: =BS!J83 -> 38.083945 | K29: =BS!K83 -> 34.213231 | L29: =BS!L83 -> 13.09641
B30: Realisation from FDs of IPO proceeds | C30: 399.14 | D30: 92.58 | E30: 0 | F30: 1050 | G30: 37.4 | H30: 0 | I30: 0 | J30: 0 | K30: 0 | L30: 0
B31: Realisation from FDs of QIP proceeds | C31: 0 | D31: 129 | E31: 783 | F31: 0 | G31: 0 | H31: 0 | I31: 0 | J31: 0 | K31: 0 | L31: 0
B32: interest received | C32: 36.35 | D32: 11.84 | E32: 129.09 | F32: 42.8 | G32: 38.72 | H32: =-H7 -> 107.56 | I32: =-I7 -> 107.56 | J32: =-J7 -> 107.56 | K32: =-K7 -> 107.56 | L32: =-L7 -> 107.56
B33: Gain on sale of investments | C33: 11.35 | D33: 10.16 | E33: 2.56 | F33: 3.66 | G33: 5.66 | H33: 0 | I33: 0 | J33: 0 | K33: 0 | L33: 0
B34: Rent income received | C34: 3.15 | D34: 2.88 | E34: 2.89 | F34: 3.55 | G34: 4.69 | H34: 0 | I34: 0 | J34: 0 | K34: 0 | L34: 0
B35: Purchase of PPE/ intangible assets/investment properties | C35: -1416.8 | D35: -1712.17 | E35: -2029.42 | F35: -2410.42 | G35: -2211.95 | H35: =-BS!H81 -> -2422.38 | I35: =-BS!I81 -> -3498.666 | J35: =-BS!J81 -> -3491.0326 | K35: =-BS!K81 -> -3136.2167 | L35: =-BS!L81 -> -1200.5057
B36: purchase of other investments | C36: 0 | D36: -3197 | E36: 0 | F36: 0 | G36: -193.08 | H36: =G36 -> -193.08 | I36: 0 | J36: 0 | K36: 0 | L36: 0
B38: Cash flow from financing activities | C38: =SUM(C39:C51) -> 208.98 | D38: =SUM(D39:D51) -> 3357.42 | E38: =SUM(E39:E51) -> -179.5 | F38: =SUM(F39:F51) -> -179.24 | G38: =SUM(G39:G51) -> -205.14 | H38: =SUM(H39:H53) -> -287.05 | I38: =SUM(I39:I53) -> -287.05 | J38: =SUM(J39:J53) -> -287.05 | K38: =SUM(K39:K53) -> -287.05 | L38: =SUM(L39:L53) -> -287.05
B39: Proceeds from of exercise of share options | C39: 0 | D39: 110.34 | E39: 0 | F39: 0 | G39: 14.63 | H39: 0 | I39: 0 | J39: 0 | K39: 0 | L39: 0
B40: Proceeds from issue of QIP (net of expenses) | C40: 0 | D40: 4076.51 | E40: 0 | F40: 0 | G40: 0 | H40: 0 | I40: 0 | J40: 0 | K40: 0 | L40: 0
B41: Proceeds from share application money pending allotment | C41: 0 | D41: 0 | E41: 0 | F41: 0 | G41: 0.91 | H41: 0 | I41: 0 | J41: 0 | K41: 0 | L41: 0
B42: Proceeds from short term borrowings | C42: =150+55 -> 205 | D42: =50 + 261.03 -> 311.03 | E42: 200 | F42: 248 | G42: 0 | H42: 0 | I42: 0 | J42: 0 | K42: 0 | L42: 0
B43: Repayment of short term borrowings | C43: -4.55 | D43: -315 | E43: -203.73 | F43: -248 | G43: 0 | H43: 0 | I43: 0 | J43: 0 | K43: 0 | L43: 0
...

Sheet DCF
B2: All amounts are in crores | C2: 2022A | D2: 2023A | E2: 2024E | F2: 2025E | G2: 2026E | H2: 2027E | I2: 2028E | K2: DASHBOARD
B3: NOPAT | D3: =IS!C15*(1-25%) -> 1101.8625 | E3: =IS!D15*(1-25%) -> 1360.4175 | F3: =IS!E15*(1-25%) -> 1143.825 | G3: =IS!F15*(1-25%) -> 1588.4325 | H3: =IS!G15*(1-25%) -> 2345.625 | I3: =IS!H15*(1-25%) -> 2940.9834
B4: Depreciation and ammortization | D4: =IS!C14 -> 212.49 | E4: =IS!D14 -> 374.41 | F4: =IS!E14 -> 414.16 | G4: =IS!F14 -> 498.08 | H4: =IS!G14 -> 638.87 | I4: =IS!H14 -> 481.27838
B5: capex | D5: =-CF!G35 -> 2211.95 | E5: =-CF!H35 -> 2422.38 | F5: =-CF!I35 -> 3498.666 | G5: =-CF!J35 -> 3491.0326 | H5: =-CF!K35 -> 3136.2167 | I5: =-CF!L35 -> 1200.5057
B6: current assets (non cash) | C6: =BS!F4-BS!F6 -> 3347.73 | D6: =BS!G4-BS!G6 -> 5241.24 | E6: =BS!H4-BS!H6 -> 6894.5836 | F6: =BS!I4-BS!I6 -> 6974.3669 | G6: =BS!J4-BS!J6 -> 8394.2462 | H6: =BS!K4-BS!K6 -> 8698.9789 | I6: =BS!L4-BS!L6 -> 10377.55
B7: current liabilities ( non debt) | C7: =0+(BS!F23-BS!F24-BS!F25) -> 1078.5 | D7: =BS!G23-BS!G24-BS!G25 -> 1300.69 | E7: =BS!H23-BS!H24-BS!H25 -> 1796.534 | F7: =BS!I23-BS!I24-BS!I25 -> 1720.8166 | G7: =BS!J23-BS!J24-BS!J25 -> 2160.0666 | H7: =BS!K23-BS!K24-BS!K25 -> 2138.8791 | I7: =BS!L23-BS!L24-BS!L25 -> 2640.8385
B8: working capital | C8: =C6-C7 -> 2269.23 | D8: =D6-D7 -> 3940.55 | E8: =E6-E7 -> 5098.0496 | F8: =F6-F7 -> 5253.5503 | G8: =G6-G7 -> 6234.1796 | H8: =H6-H7 -> 6560.0998 | I8: =I6-I7 -> 7736.7115
B9: change in working capital | D9: =D8-C8 -> 1671.32 | E9: =E8-D8 -> 1157.4996 | F9: =F8-E8 -> 155.50076 | G9: =G8-F8 -> 980.62923 | H9: =H8-G8 -> 325.92026 | I9: =I8-H8 -> 1176.6117
B10: FCFF | D10: =-(D3+D4-D5-D9) -> 2568.9175 | E10: =-(E3+E4-E5-E9) -> 1845.0521 | F10: =-(F3+F4-F5-F9) -> 2096.1818 | G10: =-(G3+G4-G5-G9) -> 2385.1493 | H10: =-(H3+H4-H5-H9) -> 477.64198 | I10: =(I3+I4-I5-I9) -> 1045.1444
B11: Terminal value | I11: =I10*(1+J11)/(WACC!C4-DCF!J11) -> 35625.8 | J11: 0.07 | K11: >>>economic growth rate
B12: cumulative fcff | D12: =D10+D11 -> 2568.9175 | E12: =E10+E11 -> 1845.0521 | F12: =F10+F11 -> 2096.1818 | G12: =G10+G11 -> 2385.1493 | H12: =H10+H11 -> 477.64198 | I12: =I10+I11 -> 36670.945
B13: wacc | D13: =WACC!C4 -> 0.1013903 | E13: =D13 -> 0.1013903 | F13: =E13 -> 0.1013903 | G13: =F13 -> 0.1013903 | H13: =G13 -> 0.1013903 | I13: =H13 -> 0.1013903
B14: present value of fcff | D14: =D12/1+D13 -> 2569.0189 | E14: =E12/(1+E13) -> 1675.2028 | F14: =F12/(1+F13)^2 -> 1728.0108 | G14: =G12/(1+G13)^3 -> 1785.2204 | H14: =H12/(1+H13)^4 -> 324.59177 | I14: =I12/(1+I13)^5 -> 22626.421
B15: enterprise value | C15: =SUM(D14:I14) -> 30708.466
B16: debt | C16: =WACC!C15 -> 642.98
B17: minority shares | C17: 0
B18: preffered shares | C18: 0
B19: cash | C19: =BS!G6 -> 207.15
B20: equity value | C20: =C15-C16-C19 -> 29858.336
B21: no of shares outstanding | C21: 65
B22: Implied share value | C22: =C20/C21 -> 459.35901
B23: dmart share price | C23: 3702
B24: premium in the market | C24: =C23/C22-1 -> 7.059056 | D24: overvalued
B25: WACC | C25: 0.1014
B26: beta | C26: 0.43
B28: Sensitivity analysis
B29: WACC AND GROWTH | J29: BETA AND GROWTH
B30: =C22 -> 459.35901 | C30: 0.09 | D30: 0.095 | E30: 0.1014 | F30: 0.105 | G30: 0.11 | J30: =C22 -> 459.35901 | K30: 0.32 | L30: 0.38 | M30: 0.43 | N30: 0.48 | O30: 0.53
B31: 0.055 | C31: 346.80354 | D31: 346.80354 | E31: 346.80354 | F31: 346.80354 | G31: 346.80354 | J31: 0.055 | K31: 346.80354 | L31: 346.80354 | M31: 346.80354 | N31: 346.80354 | O31: 346.80354
B32: 0.06 | C32: 375.25747 | D32: 375.25747 | E32: 375.25747 | F32: 375.25747 | G32: 375.25747 | J32: 0.06 | K32: 375.25747 | L32: 375.25747 | M32: 375.25747 | N32: 375.25747 | O32: 375.25747
B33: 0.065 | C33: 411.53049 | D33: 411.53049 | E33: 411.53049 | F33: 411.53049 | G33: 411.53049 | J33: 0.065 | K33: 411.53049 | L33: 411.53049 | M33: 411.53049 | N33: 411.53049 | O33: 411.53049
B34: 0.07 | C34: 459.35901 | D34: 459.35901 | E34: 459.35901 | F34: 459.35901 | G34: 459.35901 | J34: 0.07 | K34: 459.35901 | L34: 459.35901 | M34: 459.35901 | N34: 459.35901 | O34: 459.35901
B35: 0.075 | C35: 525.31105 | D35: 525.31105 | E35: 525.31105 | F35: 525.31105 | G35: 525.31105 | J35: 0.075 | K35: 525.31105 | L35: 525.31105 | M35: 525.31105 | N35: 525.31105 | O35: 525.31105
B36: 0.08 | C36: 622.09577 | D36: 622.09577 | E36: 622.09577 | F36: 622.09577 | G36: 622.09577 | J36: 0.08 | K36: 622.09577 | L36: 622.09577 | M36: 622.09577 | N36: 622.09577 | O36: 622.09577
B37: 0.085 | C37: 777.93049 | D37: 777.93049 | E37: 777.93049 | F37: 777.93049 | G37: 777.93049 | J37: 0.085 | K37: 777.93049 | L37: 777.93049 | M37: 777.93049 | N37: 777.93049 | O37: 777.93049
B38: 0.09 | C38: 1070.5788 | D38: 1070.5788 | E38: 1070.5788 | F38: 1070.5788 | G38: 1070.5788 | J38: 0.09 | K38: 1070.5788 | L38: 1070.5788 | M38: 1070.5788 | N38: 1070.5788 | O38: 1070.5788

Sheet Residual income
C2: (all numbers are in INR crores) | D2: 2020A | E2: 2021E | F2: 2022E | G2: 2023E | H2: 2024E | I2: 2025E | K2: DASHBOARD
C3: Net income | D3: =IS!G19 -> 2378.34 | E3: =IS!H19 -> 2890.4259 | F3: =IS!I19 -> 3493.6021 | G3: =IS!J19 -> 4003.6976 | H3: =IS!K19 -> 4612.7183 | I3: =IS!L19 -> 5374.4758
C4: Equity charge | E4: =AVERAGE(D5:E5)*E6 -> 1750.7986 | F4: =AVERAGE(E5:F5)*F6 -> 2017.8954 | G4: =AVERAGE(F5:G5)*G6 -> 2341.5346 | H4: =AVERAGE(G5:H5)*H6 -> 2721.6113 | I4: =AVERAGE(H5:I5)*I6 -> 3158.4218
C5: Book value | D5: =BS!G33 -> 16078.78 | E5: =BS!H33 -> 18457.04 | F5: =BS!I33 -> 21347.466 | G5: =BS!J33 -> 24841.068 | H5: =BS!K33 -> 28844.766 | I5: =BS!L33 -> 33457.484
C6: Cost of equity | E6: =WACC!C4 -> 0.1013903 | F6: =E6 -> 0.1013903 | G6: =F6 -> 0.1013903 | H6: =G6 -> 0.1013903 | I6: =H6 -> 0.1013903
C7: Residual income | E7: =E3-E4 -> 1139.6274 | F7: =F3-F4 -> 1475.7067 | G7: =G3-G4 -> 1662.163 | H7: =H3-H4 -> 1891.1069 | I7: =I3-I4 -> 2216.0539
C8: Terminal value | I8: =I7*(1+7%)/(WACC!C4-7%) -> 75538.553
C9: Cumulative cash flow | E9: =E7+E8 -> 1139.6274 | F9: =F7+F8 -> 1475.7067 | G9: =G7+G8 -> 1662.163 | H9: =H7+H8 -> 1891.1069 | I9: =I7+I8 -> 77754.606
C10: Present value of RI | E10: =E9/(1+WACC!$C$4) -> 1034.7171 | F10: =F9/(1+WACC!$C$4)^2 -> 1216.5152 | G10: =G9/(1+WACC!$C$4)^3 -> 1244.0844 | H10: =H9/(1+WACC!$C$4)^4 -> 1285.142 | I10: =I9/(1+WACC!$C$4)^5 -> 47975.542
C11: Cumuative PV of RI | D11: =SUM(E10:I10) -> 52756.001
C12: Book value | D12: =BS!G33 -> 16078.78
C13: Total expected BV | D13: =D12+D11 -> 68834.781
C14: number of shares outstanding | D14: 65
C17: Implied fair value | D17: =D13/D14 -> 1058.9966
C19: share price | D19: 3707
C20: book value per share | D20: =D12/D14 -> 247.36585
C22: price /BV | D22: =D19/D20 -> 14.985901

Sheet Relative valuation
C2: SR.No. | D2: Name | E2: price | F2: Mar Cap Rs.Cr. | G2: P/E | H2: EPS | I2: P / BV | J2: P / Sales | K2: EV / EBITDA | L2: ROE % | M2: ROCE % | N2: ROA | O2: Debt / Eq | Q2: DASHBOARD
C3: 1 | D3: Avenue Super. | E3: 3705 | F3: 241096.61 | G3: 99.09 | H3: 37.42 | I3: 14.02 | J3: 5.03 | K3: 59.12 | L3: 15.95 | M3: 20.1 | N3: 14.14 | O3: 0.04
C4: 2 | D4: Trent | E4: 4060.1 | F4: 144331.46 | G4: 177.63 | H4: 23.54 | I4: 49.12 | J4: 12.71 | K4: 73 | L4: 11.94 | M4: 11.5 | N4: 3.75 | O4: 1.66
C5: 3 | D5: Vedant Fashions | E5: 985.4 | F5: 23928.54 | G5: 58.74 | H5: 16.77 | I5: 18.05 | J5: 17.8 | K5: 34.21 | L5: 34.03 | M5: 39.17 | N5: 21.48 | O5: 0.27
C6: 4 | D6: Redtape | E6: 623.6 | F6: 8618.28 | G6: 50.76 | H6: 12.29 | I6: 5.59 | J6: 1.58 | K6: 29.11 | L6: 34.96 | M6: 44.79 | N6: 13.76 | O6: 0.85 | V6: EV / EBITDA
C7: 5 | D7: Medplus Health | E7: 690.55 | F7: 8254.65 | G7: 140.92 | H7: 4.91 | I7: 15.12 | J7: 4.91 | K7: 24.17 | L7: 3.26 | M7: 5.47 | N7: 1.77 | O7: 0.63 | V7: 59.97
C8: 6 | D8: Electronics Mart | E8: 210.6 | F8: 8102.89 | G8: 45.16 | H8: 4.67 | I8: 6.24 | J8: 1.31 | K8: 20.56 | L8: 13.79 | M8: 12 | N8: 5.43 | O8: 0.86 | V8: 72.41
C9: 7 | D9: Ethos Ltd | E9: 2425.9 | F9: 5664.26 | G9: 75.2 | H9: 32.27 | I9: 8.74 | J9: 6.12 | K9: 34.99 | L9: 13.84 | M9: 17.43 | N9: 8.61 | O9: 0.21 | V9: 34.26
V10: 24.83
F11: Median | G11: =MEDIAN(G3:G9) -> 75.2 | H11: =MEDIAN(H3:H9) -> 16.77 | I11: =MEDIAN(I3:I9) -> 14.02 | J11: =MEDIAN(J3:J9) -> 5.03 | K11: =MEDIAN(K3:K9) -> 34.21 | V11: 28.46
F12: Average | G12: =AVERAGE(G3:G9) -> 92.5 | H12: =AVERAGE(H3:H9) -> 18.838571 | I12: =AVERAGE(I3:I9) -> 16.697143 | J12: =AVERAGE(J3:J9) -> 7.0657143 | K12: =AVERAGE(K3:K9) -> 39.308571 | V12: 20.34
V13: 36.04
V14: 28.95
D15: Implied share value (AS) | I15: =ROUND(I11*$I$16,1) & " To " &ROUND(I12*I16,1) -> 3468.1 To 4130.3 | J15: =ROUND(J11*J17,1) & " To " &ROUND(J12*J17,1) -> 3325.1 To 4670.9 | K15: =ROUND(K11*K18,1) & " To " &ROUND(K12*K18,1) -> 1982.3 To 2277.7
D16: Book value per share of AS | I16: =BS!G33/DCF!C21 -> 247.36585
D17: Sales per share of AS | J17: =IS!G3/DCF!C21 -> 661.06
D18: EBITDA of AS | K18: =IS!G13/DCF!C21 -> 57.944154
D20: Weightage method of valuation
E21: DCF | G21: =DCF!C22 -> 459.35901 | H21: 0.1 | I21: =G21*H21 -> 45.935901
E22: Residual income | G22: ='Residual income'!D17 -> 1058.9966 | H22: 0.6 | I22: =G22*H22 -> 635.39798
E23: price to book value | G23: 3468 | H23: 0.2 | I23: =G23*H23 -> 693.6
E24: price to sales | G24: 3325 | H24: 0.2 | I24: =G24*H24 -> 665
I25: =SUM(I21:I24) -> 2039.9339

Sheet WACC
B2: WACC CALCULATION | D2: DASHBOARD
B4: WACC | C4: =C7*C8+C9*C10 -> 0.1013903
B5: cost of debt | C5: =IS!H26 -> 0.0289003
B6: less : tax | C6: 0.25
B7: effective cost of debt | C7: =C5*(1-C6) -> 0.021675225
B8: total debt weight | C8: =D15 -> 0.0026682106
B9: cost of equity | C9: =C20+C21*C23 -> 0.10160356
B10: total equity weight | C10: =D14 -> 0.99733179
B12: Target weight
B14: market capitalization (equity) | C14: 240335 | D14: =C14/C16 -> 0.99733179
B15: book value of debt | C15: =BS!G24+BS!G25+BS!G29+BS!G30 -> 642.98 | D15: =C15/C16 -> 0.0026682106
B16: total | C16: =SUM(C14:C15) -> 240977.98
B18: COST OF EQUITY (CAPM)
B20: Risk free rate | C20: 0.07099 | D20: https://in.investing.com/rates-bonds/india-10-year-bond-yield-historical-data
B21: Beta | C21: =K27 -> 0.43111624 | D21: self calculation
B22: Required market return | C22: 0.142 | D22: NSE
B23: Market premium | C23: =C22-C20 -> 0.07101
B25: CALCULATION OF BETA
C26: Date | D26: Dmart Adj Close | E26: Nifty Adj Close | F26: Return of dmart | G26: Return of nifty | H26: Estimated dmart return
C27: 43525 | D27: 1471.1 | E27: 11623.9 | F27: =D27/D28-1 -> 0.1355461 | G27: =E27/E28-1 -> -0.010576133 | H27: =$K$27+$K$28*G27 -> 0.43120318 | J27: Slope | K27: =SLOPE(F27:F87,G27:G87) -> 0.43111624
C28: 43556 | D28: 1295.5 | E28: 11748.15 | F28: =D28/D29-1 -> -0.020860084 | G28: =E28/E29-1 -> -0.014648356 | H28: =$K$27+$K$28*G28 -> 0.43123666 | J28: Intercept | K28: =INTERCEPT(F27:F87,G27:G87) -> -0.0082203568
C29: 43586 | D29: 1323.1 | E29: 11922.8 | F29: =D29/D30-1 -> -0.053508868 | G29: =E29/E30-1 -> 0.011362448 | H29: =$K$27+$K$28*G29 -> 0.43102284
C30: 43617 | D30: 1397.9 | E30: 11788.85 | F30: =D30/D31-1 -> -0.057192911 | G30: =E30/E31-1 -> 0.060339055 | H30: =$K$27+$K$28*G30 -> 0.43062023
C31: 43647 | D31: 1482.7 | E31: 11118 | F31: =D31/D32-1 -> -0.056296389 | G31: =E31/E32-1 -> 0.0085954687 | H31: =$K$27+$K$28*G31 -> 0.43104558
C32: 43678 | D32: 1571.15 | E32: 11023.25 | F32: =D32/D33-1 -> -0.15556807 | G32: =E32/E33-1 -> -0.039322162 | H32: =$K$27+$K$28*G32 -> 0.43143948
C33: 43709 | D33: 1860.6 | E33: 11474.45 | F33: =D33/D34-1 -> -0.067204796 | G33: =E33/E34-1 -> -0.033929841 | H33: =$K$27+$K$28*G33 -> 0.43139516
C34: 43739 | D34: 1994.65 | E34: 11877.45 | F34: =D34/D35-1 -> 0.094458175 | G34: =E34/E35-1 -> -0.014814107 | H34: =$K$27+$K$28*G34 -> 0.43123802
C35: 43770 | D35: 1822.5 | E35: 12056.05 | F35: =D35/D36-1 -> -0.0086218491 | G35: =E35/E36-1 -> -0.0092370341 | H35: =$K$27+$K$28*G35 -> 0.43119217
C36: 43800 | D36: 1838.35 | E36: 12168.45 | F36: =D36/D37-1 -> -0.13852245 | G36: =E36/E37-1 -> 0.017250365 | H36: =$K$27+$K$28*G36 -> 0.43097444
C37: 43831 | D37: 2133.95 | E37: 11962.1 | F37: =D37/D38-1 -> -0.081757355 | G37: =E37/E38-1 -> 0.067877752 | H37: =$K$27+$K$28*G37 -> 0.43055826
C38: 43862 | D38: 2323.95 | E38: 11201.75 | F38: =D38/D39-1 -> 0.06237712 | G38: =E38/E39-1 -> 0.30286994 | H38: =$K$27+$K$28*G38 -> 0.42862654
C39: 43891 | D39: 2187.5 | E39: 8597.75 | F39: =D39/D40-1 -> -0.082289728 | G39: =E39/E40-1 -> -0.12800843 | H39: =$K$27+$K$28*G39 -> 0.43216852
C40: 43922 | D40: 2383.6499 | E40: 9859.9004 | F40: =D40/D41-1 -> 0.050366757 | G40: =E40/E41-1 -> 0.029184952 | H40: =$K$27+$K$28*G40 -> 0.43087633
... C86: 45323 | D86: 3693.3 | E86: 22040.699 | F86: =D86/D87-1 -> 0 | G86: =E86/E87-1 -> 0 | H86: =$K$27+$K$28*G86 -> 0.43111624
C87: 45338 | D87: 3693.3 | E87: 22040.699 | F87: - | G87: - | H87: =$K$27+$K$28*G87 -> #VALUE!

Sheet Ratio Analysis
B2: Profitability ratio | C2: 2019A | D2: 2020A | E2: 2021A | F2: 2022A | G2: 2023A | I2: DASHBOARD
B3: Gross profit margin | C3: =IS!C9/IS!C3 -> 0.15219916 | D3: =IS!D9/IS!D3 -> 0.15351909 | E3: =IS!E9/IS!E3 -> 0.15549316 | F3: =IS!F9/IS!F3 -> 0.15103899 | G3: =IS!G9/IS!G3 -> 0.15324921
B4: operating profit margin | C4: =IS!C15/IS!C3 -> 0.073263827 | D4: =IS!D15/IS!D3 -> 0.072758772 | E4: =IS!E15/IS!E3 -> 0.062660055 | F4: =IS!F15/IS!F3 -> 0.068113667 | G4: =IS!G15/IS!G3 -> 0.0727852
B5: net profit margin | C5: =IS!C19/IS!C3 -> 0.045004032 | D5: =IS!D19/IS!D3 -> 0.052184921 | E5: =IS!E19/IS!E3 -> 0.045171034 | F5: =IS!F19/IS!F3 -> 0.047996768 | G5: =IS!G19/IS!G3 -> 0.055350265
B6: return on asset | C6: =IS!C15*(1-IS!C18/IS!C17)/AVERAGE(BS!B3:C3) -> 0.13309448 | D6: =IS!D15*(1-IS!D18/IS!D17)/AVERAGE(BS!C3:D3) -> 0.14175736 | E6: =IS!E15*(1-IS!E18/IS!E17)/AVERAGE(BS!D3:E3) -> 0.087850119 | F6: =IS!F15*(1-IS!F18/IS!F17)/AVERAGE(BS!E3:F3) -> 0.10514001 | G6: =IS!G15*(1-IS!G18/IS!G17)/AVERAGE(BS!F3:G3) -> 0.14477721
B7: return on equity | C7: =IS!C19/BS!C34 -> 0.16151554 | D7: =IS!D19/BS!D34 -> 0.11741972 | E7: =IS!E19/BS!E34 -> 0.090237703 | F7: =IS!F19/BS!F34 -> 0.10911239 | G7: =IS!G19/BS!G34 -> 0.14791868
B9: Liquidity ratio | C9: 2019A | D9: 2020A | E9: 2021A | F9: 2022A | G9: 2023A
B10: current ratio | C10: =BS!C4/BS!C23 -> 1.6974049 | D10: =BS!D4/BS!D23 -> 3.2345963 | E10: =BS!E4/BS!E23 -> 3.6726715 | F10: =BS!F4/BS!F23 -> 2.8259692 | G10: =BS!G4/BS!G23 -> 3.713942
B11: quick ratio | C11: =(BS!C4-BS!C5)/BS!C23 -> 0.3862762 | D11: =(BS!D4-BS!D5)/BS!D23 -> 0.55148801 | E11: =(BS!E4-BS!E5)/BS!E23 -> 1.6394458 | F11: =(BS!F4-BS!F5)/BS!F23 -> 0.5747318 | G11: =(BS!G4-BS!G5)/BS!G23 -> 1.5029959
B12: cash ratio | C12: =BS!C6/BS!C23 -> 0.10186483 | D12: =BS!D6/BS!D23 -> 0.14586663 | E12: =BS!E6/BS!E23 -> 0.17318249 | F12: =BS!F6/BS!F23 -> 0.078076648 | G12: =BS!G6/BS!G23 -> 0.14120558
B14: solvency ratio | C14: 2019A | D14: 2020A | E14: 2021A | F14: 2022A | G14: 2023A
B15: debt to equity ratio | C15: =(BS!C24+BS!C25+BS!C29+BS!C30)/BS!C34 -> 0.076925968 | D15: =(BS!D24+BS!D25+BS!D29+BS!D30)/BS!D34 -> 0.027003341 | E15: =(BS!E24+BS!E25+BS!E29+BS!E30)/BS!E34 -> 0.032232382 | F15: =(BS!F24+BS!F25+BS!F29+BS!F30)/BS!F34 -> 0.047299095 | G15: =(BS!G24+BS!G25+BS!G29+BS!G30)/BS!G34 -> 0.039989551
B16: asset to equity ratio | C16: =BS!C3/BS!C34 -> 1.2538314 | D16: =BS!D3/BS!D34 -> 1.0899579 | E16: =BS!E3/BS!E34 -> 1.1208384 | F16: =BS!F3/BS!F34 -> 1.1312361 | G16: =BS!G3/BS!G34 -> 1.1261041
B17: interest coverage ratio | C17: =IS!C15/IS!C16 -> 31.119466 | D17: =IS!D15/IS!D16 -> 26.242622 | E17: =IS!E15/IS!E16 -> 36.617047 | F17: =IS!F15/IS!F16 -> 39.373675 | G17: =IS!G15/IS!G16 -> 46.395194
B19: Activity ratio | C19: 2019A | D19: 2020A | E19: 2021A | F19: 2022A | G19: 2023A
B20: Asset turnover ratio | C20: =IS!C3/BS!C3 -> 2.8623568 | D20: =IS!D3/BS!D3 -> 2.0643641 | E20: =IS!E3/BS!E3 -> 1.7823172 | F20: =IS!F3/BS!F3 -> 2.0095963 | G20: =IS!G3/BS!G3 -> 2.3731477
B21: Accounts payable turnover | C21: =IS!C6/AVERAGE(BS!B26:C26) -> 36.697477 | D21: =IS!D6/AVERAGE(BS!C26:D26) -> 47.066933 | E21: =IS!E6/AVERAGE(BS!D26:E26) -> 40.638763 | F21: =IS!F6/AVERAGE(BS!E26:F26) -> 45.226954 | G21: =IS!G6/AVERAGE(BS!F26:G26) -> 54.183501
B22: Account inventory turnover | C22: =IS!C6/AVERAGE(BS!B5:C5) -> 10.56839 | D22: =IS!D6/AVERAGE(BS!C5:D5) -> 11.868748 | E22: =IS!E6/AVERAGE(BS!D5:E5) -> 9.7980208 | F22: =IS!F6/AVERAGE(BS!E5:F5) -> 10.578124 | G22: =IS!G6/AVERAGE(BS!F5:G5) -> 12.156064
B23: Accounts receivable turnover | C23: =IS!C3/AVERAGE(BS!B7:C7) -> 311.52509 | D23: =IS!D3/AVERAGE(BS!C7:D7) -> 594.1418 | E23: =IS!E3/AVERAGE(BS!D7:E7) -> 771.08411 | F23: =IS!F3/AVERAGE(BS!E7:F7) -> 562.93582 | G23: =IS!G3/AVERAGE(BS!F7:G7) -> 665.92639
B25: Days payables | C25: =365/C21 -> 9.946188 | D25: =365/D21 -> 7.7549137 | E25: =365/E21 -> 8.9815726 | F25: =365/F21 -> 8.0704087 | G25: =365/G21 -> 6.736368
B26: Days inventory outstanding | C26: =365/C22 -> 34.536955 | D26: =365/D22 -> 30.753034 | E26: =365/E22 -> 37.252421 | F26: =365/F22 -> 34.505175 | G26: =365/G22 -> 30.026167
B27: Days receivables | C27: =365/C23 -> 1.1716552 | D27: =365/D23 -> 0.61433146 | E27: =365/E23 -> 0.47335951 | F27: =365/F23 -> 0.64838653 | G27: =365/G23 -> 0.54810863
B28: cash conversion cycle | C28: =C27+C26-C25 -> 25.762423 | D28: =D27+D26-D25 -> 23.612452 | E28: =E27+E26-E25 -> 28.744208 | F28: =F27+F26-F25 -> 27.083152 | G28: =G27+G26-G25 -> 23.837907
E30: bm accounts payable
B31: average days payable | C31: =AVERAGE(C25:G25) -> 8.2978902 | E31: =365/C31 -> 43.987085
B32: average inventory outstanding | C32: =AVERAGE(C26:G26) -> 33.41475 | E32: =365/C32 -> 10.92332
B33: average days receivable | C33: =AVERAGE(C27:G27) -> 0.69116827 | E33: =365/C33 -> 528.09137

Sheet Charts
P2: DASHBOARD
