Workbook

Sheet Revenue & Cost
C3: 1QFY21 | D3: 2QFY21 | E3: 3QFY21 | F3: 4QFY21 | G3: 1QFY22 | H3: 2QFY22 | I3: 3QFY22 | J3: 4QFY22 | K3: 1QFY23 | L3: 2QFY23 | M3: 3QFY23 | N3: 4QFY23 | O3: 1QFY24 | P3: 2QFY24 | Q3: 3QFY24 | R3: 4QFY24 | S3: 1QFY25 | T3: 2QFY25 | U3: 3QFY25 | V3: 4QFY25 | W3: 1QFY26 | X3: 2QFY26 | Y3: 3QFY26 | Z3: 4QFY26E | AA3: 1QFY27E | AB3: 2QFY27E | AC3: 3QFY27E | AD3: 4QFY27E | AE3: 1QFY28E | AF3: 2QFY28E | AG3: 3QFY28E | AH3: 4QFY28E
B4: Payment GMV (Rs bn) | C4: 697 | D4: 947 | E4: 1121 | F4: 1268 | G4: 1469 | H4: 1956 | I4: 2500 | J4: 2590 | K4: 2960 | L4: 3180 | M4: 3460 | N4: 3620 | O4: 4050 | P4: 4500 | Q4: 5100 | R4: 4690 | S4: 4260 | T4: 4500 | U4: 5040 | V4: 5100 | W4: 5400 | X4: 5700 | Y4: 6200 | Z4: =(Z8*Z12)/1000 -> 6283.6958 | AA4: =(AA8*AA12)/1000 -> 6602.9755 | AB4: =(AB8*AB12)/1000 -> 7014.4143 | AC4: =(AC8*AC12)/1000 -> 7679.9092 | AD4: =(AD8*AD12)/1000 -> 7821.9256 | AE4: =(AE8*AE12)/1000 -> 8219.364 | AF4: =(AF8*AF12)/1000 -> 8731.5217 | AG4: =(AG8*AG12)/1000 -> 9559.9279 | AH4: =(AH8*AH12)/1000 -> 9736.7094
B5: Growth YoY (%) | G5: =+G4/C4-1 -> 1.107604 | H5: =+H4/D4-1 -> 1.0654699 | I5: =+I4/E4-1 -> 1.2301517 | J5: =+J4/F4-1 -> 1.0425868 | K5: =+K4/G4-1 -> 1.0149762 | L5: =+L4/H4-1 -> 0.62576687 | M5: =+M4/I4-1 -> 0.384 | N5: =+N4/J4-1 -> 0.3976834 | ... AH5: =+AH4/AD4-1 -> 0.24479698
B6: Growth QoQ (%) | D6: =D4/C4-1 -> 0.35868006 | E6: =E4/D4-1 -> 0.18373812 | F6: =F4/E4-1 -> 0.13113292 | G6: =G4/F4-1 -> 0.15851735 | H6: =H4/G4-1 -> 0.33151804 | I6: =I4/H4-1 -> 0.27811861 | J6: =J4/I4-1 -> 0.036 | K6: =K4/J4-1 -> 0.14285714 | ... AH6: =AH4/AG4-1 -> 0.018491935
B8: Average MTU (mn) | C8: 39.8 | D8: 43.1 | E8: 47.1 | F8: 50.4 | G8: 50.4 | H8: 57.4 | I8: 64.4 | J8: 70.9 | K8: 74.8 | L8: 79.7 | M8: 84.9 | N8: 89 | O8: 92 | P8: 95 | Q8: 100 | R8: 96 | S8: 78 | T8: 71 | U8: 70 | V8: 72 | W8: 74 | X8: 75 | Y8: 76 | Z8: =Y8*(1+Z10) -> 77.14 | AA8: =Z8*(1+AA10) -> 78.6828 | AB8: =AA8*(1+AB10) -> 80.256456 | AC8: =AB8*(1+AC10) -> 81.861585 | AD8: =AC8*(1+AD10) -> 83.498817 | AE8: =AD8*(1+AE10) -> 85.168793 | AF8: =AE8*(1+AF10) -> 86.872169 | AG8: =AF8*(1+AG10) -> 88.609612 | AH8: =AG8*(1+AH10) -> 90.381805
B9: Growth YoY (%) | G9: =+G8/C8-1 -> 0.26633166 | H9: =+H8/D8-1 -> 0.33178654 | I9: =+I8/E8-1 -> 0.36730361 | J9: =+J8/F8-1 -> 0.40674603 | K9: =+K8/G8-1 -> 0.48412698 | L9: =+L8/H8-1 -> 0.38850174 | M9: =+M8/I8-1 -> 0.31832298 | N9: =+N8/J8-1 -> 0.25528914 | ... Y9: =+Y8/U8-1 -> 0.085714286
B10: Growth QoQ (%) | D10: =D8/C8-1 -> 0.082914573 | E10: =E8/D8-1 -> 0.092807425 | F10: =F8/E8-1 -> 0.070063694 | G10: =G8/F8-1 -> 0 | H10: =H8/G8-1 -> 0.13888889 | I10: =I8/H8-1 -> 0.12195122 | J10: =J8/I8-1 -> 0.10093168 | K10: =K8/J8-1 -> 0.055007052 | ... Y10: =Y8/X8-1 -> 0.013333333 | Z10: 0.015 | AA10: 0.02 | AB10: 0.02 | AC10: 0.02 | AD10: 0.02 | AE10: 0.02 | AF10: 0.02 | AG10: 0.02 | AH10: 0.02
B12: GMV/MTU (Rs.) | C12: =C4*1000/C8 -> 17512.563 | D12: =D4*1000/D8 -> 21972.158 | E12: =E4*1000/E8 -> 23800.425 | F12: =F4*1000/F8 -> 25158.73 | G12: =G4*1000/G8 -> 29146.825 | H12: =H4*1000/H8 -> 34076.655 | I12: =I4*1000/I8 -> 38819.876 | J12: =J4*1000/J8 -> 36530.324 | ... Y12: =Y4*1000/Y8 -> 81578.947 | Z12: =V12*(1+Z13) -> 81458.333 | AA12: =W12*(1+AA13) -> 83918.919 | AB12: =X12*(1+AB13) -> 87400 | AC12: =Y12*(1+AC13) -> 93815.789 | AD12: =Z12*(1+AD13) -> 93677.083 | AE12: =AA12*(1+AE13) -> 96506.757 | AF12: =AB12*(1+AF13) -> 100510 | AG12: =AC12*(1+AG13) -> 107888.16 | AH12: =AD12*(1+AH13) -> 107728.65
B13: Growth YoY (%) | G13: =+G12/C12-1 -> 0.66433809 | H13: =+H12/D12-1 -> 0.55090162 | I13: =+I12/E12-1 -> 0.63105812 | J13: =+J12/F12-1 -> 0.45199397 | K13: =+K12/G12-1 -> 0.35768448 | L13: =+L12/H12-1 -> 0.17087852 | M13: =+M12/I12-1 -> 0.04981861 | N13: =+N12/J12-1 -> 0.11343543 | ... Y13: =+Y12/U12-1 -> 0.13304094 | Z13: 0.15 | AA13: 0.15 | AB13: 0.15 | AC13: 0.15 | AD13: 0.15 | AE13: 0.15 | AF13: 0.15 | AG13: 0.15 | AH13: 0.15
B15: Take rate | C15: =IS!C4/('Revenue & Cost'!C4*1000) -> 0.005830703 | D15: =IS!D4/('Revenue & Cost'!D4*1000) -> 0.0049894403 | E15: =IS!E4/('Revenue & Cost'!E4*1000) -> 0.0046681534 | F15: =IS!F4/('Revenue & Cost'!F4*1000) -> 0.0045630915 | G15: =IS!G4/('Revenue & Cost'!G4*1000) -> 0.0043192648 | H15: =IS!H4/('Revenue & Cost'!H4*1000) -> 0.0038542945 | I15: =IS!I4/('Revenue & Cost'!I4*1000) -> 0.0039664 | J15: =IS!J4/('Revenue & Cost'!J4*1000) -> 0.0040173745 | ... Y15: =IS!Y4/('Revenue & Cost'!Y4*1000) -> 0.0019225806 | Z15: =Y15 -> 0.0019225806 | AA15: =Z15 -> 0.0019225806 | AB15: =AA15 -> 0.0019225806 | AC15: =AB15 -> 0.0019225806 | AD15: =AC15 -> 0.0019225806 | AE15: =AD15 -> 0.0019225806 | AF15: =AE15 -> 0.0019225806 | AG15: =AF15 -> 0.0019225806 | AH15: =AG15 -> 0.0019225806
B17: Total Payments revenue | C17: 4064 | D17: 4725 | E17: 5233 | F17: 5786 | G17: 6345 | H17: 7539 | I17: 9916 | J17: 10405 | K17: 10760 | L17: 11730 | M17: 11530 | N17: 14420 | O17: 13960 | P17: 15006 | Q17: 16790 | R17: 15550 | S17: 8840 | T17: 9460 | U17: 10030 | V17: 10460 | W17: 10440 | X17: 11460 | Y17: 11920 | Z17: =Z4*1000*Z15 -> 12080.912 | AA17: =AA4*1000*AA15 -> 12694.753 | AB17: =AB4*1000*AB15 -> 13485.777 | AC17: =AC4*1000*AC15 -> 14765.245 | AD17: =AD4*1000*AD15 -> 15038.283 | AE17: =AE4*1000*AE15 -> 15802.39 | AF17: =AF4*1000*AF15 -> 16787.055 | AG17: =AG4*1000*AG15 -> 18379.732 | AH17: =AH4*1000*AH15 -> 18719.609
B19: Total Financial Service Revenue | C19: 234 | D19: 253 | E19: 416 | F19: 381 | G19: 549 | H19: 887 | I19: 1252 | J19: 1684 | K19: 2710 | L19: 3490 | M19: 4460 | N19: 4750 | O19: 5220 | P19: 5710 | Q19: 6070 | R19: 3040 | S19: 2800 | T19: 3760 | U19: 5020 | V19: 5450 | W19: 5605 | X19: 6110 | Y19: 6720 | Z19: =Y19*(1+Z20) -> 7390.9002 | AA19: =Z19*(1+AA20) -> 8128.7805 | AB19: =AA19*(1+AB20) -> 8940.3282 | AC19: =AB19*(1+AC20) -> 9832.8978 | AD19: =AC19*(1+AD20) -> 10814.578 | AE19: =AD19*(1+AE20) -> 11894.266 | AF19: =AE19*(1+AF20) -> 13081.746 | AG19: =AF19*(1+AG20) -> 14387.78 | AH19: =AG19*(1+AH20) -> 15824.203
B20: Growth QoQ (%) | D20: =D19/C19-1 -> 0.081196581 | E20: =E19/D19-1 -> 0.64426877 | F20: =F19/E19-1 -> -0.084134615 | G20: =G19/F19-1 -> 0.44094488 | H20: =H19/G19-1 -> 0.61566485 | I20: =I19/H19-1 -> 0.41149944 | J20: =J19/I19-1 -> 0.34504792 | K20: =K19/J19-1 -> 0.60926366 | ... Y20: =Y19/X19-1 -> 0.099836334 | Z20: =Y20 -> 0.099836334 | AA20: =Z20 -> 0.099836334 | AB20: =AA20 -> 0.099836334 | AC20: =AB20 -> 0.099836334 | AD20: =AC20 -> 0.099836334 | AE20: =AD20 -> 0.099836334 | AF20: =AE20 -> 0.099836334 | AG20: =AF20 -> 0.099836334 | AH20: =AG20 -> 0.099836334
B21: Growth YoY (%) | G21: =G19/C19-1 -> 1.3461538 | H21: =H19/D19-1 -> 2.5059289 | I21: =I19/E19-1 -> 2.0096154 | J21: =J19/F19-1 -> 3.4199475 | K21: =K19/G19-1 -> 3.9362477 | L21: =L19/H19-1 -> 2.934611 | M21: =M19/I19-1 -> 2.5623003 | N21: =N19/J19-1 -> 1.8206651 | ... Y21: =Y19/U19-1 -> 0.33864542
B23: Total marketing revenue (commerce and cloud) | C23: 1214 | D23: 1661 | E23: 2071 | F23: 1986 | G23: 2014 | H23: 2438 | I23: 3393 | J23: 3203 | K23: 3329 | L23: 3770 | M23: 4200 | N23: 3930 | O23: 4050 | P23: 4230 | Q23: 5140 | R23: 3950 | S23: 3210 | T23: 3020 | U23: 2670 | V23: 2670 | W23: 2465 | X23: 2280 | Y23: 2380 | Z23: =Y23*(1+Z24) -> 2484.386 | AA23: =Z23*(1+AA24) -> 2593.3503 | AB23: =AA23*(1+AB24) -> 2707.0937 | AC23: =AB23*(1+AC24) -> 2825.8259 | AD23: =AC23*(1+AD24) -> 2949.7656 | AE23: =AD23*(1+AE24) -> 3079.1413 | AF23: =AE23*(1+AF24) -> 3214.1913 | AG23: =AF23*(1+AG24) -> 3355.1647 | AH23: =AG23*(1+AH24) -> 3502.321
B24: Growth QoQ (%) | D24: =D23/C23-1 -> 0.36820428 | E24: =E23/D23-1 -> 0.24683925 | F24: =F23/E23-1 -> -0.041042974 | G24: =G23/F23-1 -> 0.014098691 | H24: =H23/G23-1 -> 0.21052632 | I24: =I23/H23-1 -> 0.39171452 | J24: =J23/I23-1 -> -0.055997642 | K24: =K23/J23-1 -> 0.039338121 | ... Y24: =Y23/X23-1 -> 0.043859649 | Z24: =Y24 -> 0.043859649 | AA24: =Z24 -> 0.043859649 | AB24: =AA24 -> 0.043859649 | AC24: =AB24 -> 0.043859649 | AD24: =AC24 -> 0.043859649 | AE24: =AD24 -> 0.043859649 | AF24: =AE24 -> 0.043859649 | AG24: =AF24 -> 0.043859649 | AH24: =AG24 -> 0.043859649
B25: Growth YoY (%) | G25: =G23/C23-1 -> 0.65897858 | H25: =H23/D23-1 -> 0.46779049 | I25: =I23/E23-1 -> 0.63833897 | J25: =J23/F23-1 -> 0.61278953 | K25: =K23/G23-1 -> 0.65292949 | L25: =L23/H23-1 -> 0.54634947 | M25: =M23/I23-1 -> 0.23784262 | N25: =N23/J23-1 -> 0.22697471 | ... Y25: =Y23/U23-1 -> -0.10861423 | Z25: =Y25 -> -0.10861423 | AA25: =Z25 -> -0.10861423 | AB25: =AA25 -> -0.10861423 | AC25: =AB25 -> -0.10861423 | AD25: =AC25 -> -0.10861423 | AE25: =AD25 -> -0.10861423 | AF25: =AE25 -> -0.10861423 | AG25: =AF25 -> -0.10861423 | AH25: =AG25 -> -0.10861423
B27: Total other revenue | C27: 0 | D27: 0 | E27: 0 | F27: 0 | G27: 0 | H27: 0 | I27: 0 | J27: 117 | K27: -3 | L27: 150 | M27: 432 | N27: 245 | O27: 186 | P27: 240 | Q27: 505 | R27: 130 | S27: 166 | T27: 355 | U27: 558 | V27: 535 | W27: 665 | X27: 770 | Y27: 920 | Z27: =Y27*(1+Z28) -> 1099.2208 | AA27: =Z27*(1+AA28) -> 1313.3547 | AB27: =AA27*(1+AB28) -> 1569.203 | AC27: =AB27*(1+AC28) -> 1874.8919 | AD27: =AC27*(1+AD28) -> 2240.1306 | AE27: =AD27*(1+AE28) -> 2676.5197 | AF27: =AE27*(1+AF28) -> 3197.9196 | AG27: =AF27*(1+AG28) -> 3820.891 | AH27: =AG27*(1+AH28) -> 4565.2204
B28: Growth QoQ (%) | K28: =K27/J27-1 -> -1.025641 | L28: =L27/K27-1 -> -51 | M28: =M27/L27-1 -> 1.88 | N28: =N27/M27-1 -> -0.43287037 | O28: =O27/N27-1 -> -0.24081633 | P28: =P27/O27-1 -> 0.29032258 | Q28: =Q27/P27-1 -> 1.1041667 | R28: =R27/Q27-1 -> -0.74257426 | ... Y28: =Y27/X27-1 -> 0.19480519 | Z28: =Y28 -> 0.19480519 | AA28: =Z28 -> 0.19480519 | AB28: =AA28 -> 0.19480519 | AC28: =AB28 -> 0.19480519 | AD28: =AC28 -> 0.19480519 | AE28: =AD28 -> 0.19480519 | AF28: =AE28 -> 0.19480519 | AG28: =AF28 -> 0.19480519 | AH28: =AG28 -> 0.19480519
B29: Growth YoY (%) | O29: =O27/K27-1 -> -63 | P29: =P27/L27-1 -> 0.6 | Q29: =Q27/M27-1 -> 0.16898148 | R29: =R27/N27-1 -> -0.46938776 | S29: =S27/O27-1 -> -0.10752688 | T29: =T27/P27-1 -> 0.47916667 | U29: =U27/Q27-1 -> 0.1049505 | V29: =V27/R27-1 -> 3.1153846 | ... Y29: =Y27/U27-1 -> 0.64874552
B30: Total Revenue | C30: =C27+C23+C19+C17 -> 5512 | D30: =D27+D23+D19+D17 -> 6639 | E30: =E27+E23+E19+E17 -> 7720 | F30: =F27+F23+F19+F17 -> 8153 | G30: =G27+G23+G19+G17 -> 8908 | H30: =H27+H23+H19+H17 -> 10864 | I30: =I27+I23+I19+I17 -> 14561 | J30: =J27+J23+J19+J17 -> 15409 | ... AH30: =AH27+AH23+AH19+AH17 -> 42611.353
B32: COST
B33: Payment Processing Charge | C33: 3980 | D33: 4924 | E33: 5177 | F33: 5087 | G33: 5265 | H33: 6700 | I33: 7831 | J33: 7742 | K33: 6938 | L33: 7458 | M33: 7378 | N33: 7803 | O33: 7666 | P33: 8167 | Q33: 9822 | R33: 7148 | S33: 5171 | T33: 5168 | U33: 5704 | V33: 5204 | W33: 5809 | X33: 6290 | Y33: 6710 | Z33: =Z4*1000*Z34 -> 6800.5805 | AA33: =AA4*1000*AA34 -> 7146.1235 | AB33: =AB4*1000*AB34 -> 7591.4064 | AC33: =AC4*1000*AC34 -> 8311.6437 | AD33: =AD4*1000*AD34 -> 8465.3421 | AE33: =AE4*1000*AE34 -> 8895.473 | AF33: =AF4*1000*AF34 -> 9449.7598 | AG33: =AG4*1000*AG34 -> 10346.309 | AH33: =AH4*1000*AH34 -> 10537.632
B34: as % of GMV | C34: =C33/(C4*1000) -> 0.0057101865 | D34: =D33/(D4*1000) -> 0.0051995776 | E34: =E33/(E4*1000) -> 0.004618198 | F34: =F33/(F4*1000) -> 0.0040118297 | G34: =G33/(G4*1000) -> 0.0035840708 | H34: =H33/(H4*1000) -> 0.0034253579 | I34: =I33/(I4*1000) -> 0.0031324 | J34: =J33/(J4*1000) -> 0.0029891892 | ... Y34: =Y33/(Y4*1000) -> 0.0010822581 | Z34: =Y34 -> 0.0010822581 | AA34: =Z34 -> 0.0010822581 | AB34: =AA34 -> 0.0010822581 | AC34: =AB34 -> 0.0010822581 | AD34: =AC34 -> 0.0010822581 | AE34: =AD34 -> 0.0010822581 | AF34: =AE34 -> 0.0010822581 | AG34: =AF34 -> 0.0010822581 | AH34: =AG34 -> 0.0010822581
B36: Marketing & promotional expenses | C36: 841 | D36: 1365 | E36: 2118 | F36: 1001 | G36: 1377 | H36: 1857 | I36: 2831 | J36: 2489 | K36: 3181 | L36: 3275 | M36: 2263 | N36: 2045 | O36: 2653 | P36: 2528 | Q36: 2752 | R36: 1287 | S36: 2214 | T36: 1544 | U36: 1409 | V36: 1427 | W36: 998 | X36: 1220 | Y36: 1460 | Z36: =Z30*Z37 -> 1613.8793 | AA36: =AA30*AA37 -> 1731.1167 | AB36: =AB30*AB37 -> 1869.1681 | AC36: =AC30*AC37 -> 2050.9202 | AD36: =AD30*AD37 -> 2172.993 | AE36: =AE30*AE37 -> 2341.6622 | AF36: =AF30*AF37 -> 2539.6638 | AG36: =AG30*AG37 -> 2796.0497 | AH36: =AH30*AH37 -> 2982.7947
B37: as % of total revenue | C37: =C36/C30 -> 0.1525762 | D37: =D36/D30 -> 0.20560325 | E37: =E36/E30 -> 0.27435233 | F37: =F36/F30 -> 0.12277689 | G37: =G36/G30 -> 0.15458015 | H37: =H36/H30 -> 0.17093152 | I37: =I36/I30 -> 0.19442346 | J37: =J36/J30 -> 0.16152898 | ... Y37: =Y36/Y30 -> 0.066545123 | Z37: 0.07 | AA37: 0.07 | AB37: 0.07 | AC37: 0.07 | AD37: 0.07 | AE37: 0.07 | AF37: 0.07 | AG37: 0.07 | AH37: 0.07
B39: Employee Benefit Expense | C39: 2138 | D39: 2862 | E39: 3371 | F39: 3478 | G39: 3507 | H39: 3865 | I39: 8313 | J39: 8634 | K39: 9117 | L39: 9441 | M39: 9456 | N39: 9769 | O39: 11061 | P39: 11915 | Q39: 11872 | R39: 11044 | S39: 9525 | T39: 8310 | U39: 7563 | V39: 7483 | W39: 6426 | X39: 6630 | Y39: 7210 | Z39: =Z30*Z40 -> 6916.6257 | AA39: =AA30*AA40 -> 7419.0715 | AB39: =AB30*AB40 -> 8010.7206 | AC39: =AC30*AC40 -> 8789.6581 | AD39: =AD30*AD40 -> 9312.8272 | AE39: =AE30*AE40 -> 10035.695 | AF39: =AF30*AF40 -> 10884.273 | AG39: =AG30*AG40 -> 11983.07 | AH39: =AH30*AH40 -> 12783.406
B40: as % of total revenue | C40: =C39/C30 -> 0.38788099 | D40: =D39/D30 -> 0.43108902 | E40: =E39/E30 -> 0.43665803 | F40: =F39/F30 -> 0.42659144 | G40: =G39/G30 -> 0.39369106 | H40: =H39/H30 -> 0.35576215 | I40: =I39/I30 -> 0.57090859 | J40: =J39/J30 -> 0.56032189 | ... Y40: =Y39/Y30 -> 0.32862352 | Z40: 0.3 | AA40: 0.3 | AB40: 0.3 | AC40: 0.3 | AD40: 0.3 | AE40: 0.3 | AF40: 0.3 | AG40: 0.3 | AH40: 0.3
B42: Software, cloud and data center expenses | C42: 746 | D42: 721 | E42: 951 | F42: 1080 | G42: 1058 | H42: 1129 | I42: 1301 | J42: 1511 | K42: 1622 | L42: 1728 | M42: 1709 | N42: 1880 | O42: 1550 | P42: 1553 | Q42: 1704 | R42: 1623 | S42: 1824 | T42: 1578 | U42: 1536 | V42: 1459 | W42: 1677 | X42: 1330 | Y42: 1670 | Z42: =Z30*Z43 -> 1844.4335 | AA42: =AA30*AA43 -> 1978.4191 | AB42: =AB30*AB43 -> 2136.1922 | AC42: =AC30*AC43 -> 2343.9088 | AD42: =AD30*AD43 -> 2483.4206 | AE42: =AE30*AE43 -> 2676.1854 | AF42: =AF30*AF43 -> 2902.4729 | AG42: =AG30*AG43 -> 3195.4854 | AH42: =AH30*AH43 -> 3408.9083
B43: as % of total revenue | C43: =C42/C30 -> 0.13534107 | D43: =D42/D30 -> 0.10860069 | E43: =E42/E30 -> 0.12318653 | F43: =F42/F30 -> 0.13246658 | G43: =G42/G30 -> 0.11876965 | H43: =H42/H30 -> 0.10392121 | I43: =I42/I30 -> 0.089348259 | J43: =J42/J30 -> 0.098059576 | ... Y43: =Y42/Y30 -> 0.076116682 | Z43: 0.08 | AA43: 0.08 | AB43: 0.08 | AC43: 0.08 | AD43: 0.08 | AE43: 0.08 | AF43: 0.08 | AG43: 0.08 | AH43: 0.08
B45: Other expenses | C45: 1123 | D45: 1223 | E45: 1393 | F45: 2118 | G45: 1410 | H45: 1837 | I45: 2164 | J45: 2323 | K45: 2277 | L45: 2616 | M45: 3123 | N45: 3139 | O45: 3413 | P45: 3333 | Q45: 3950 | R45: 3804 | S45: 4204 | T45: 4028 | U45: 4290 | V45: 4428 | W45: 3550 | X45: 3730 | Y45: 3330 | Z45: =Z30*Z46 -> 3458.3128 | AA45: =AA30*AA46 -> 3709.5358 | AB45: =AB30*AB46 -> 4005.3603 | AC45: =AC30*AC46 -> 4394.8291 | AD45: =AD30*AD46 -> 4656.4136 | AE45: =AE30*AE46 -> 5017.8476 | AF45: =AF30*AF46 -> 5442.1367 | AG45: =AG30*AG46 -> 5991.5351 | AH45: =AH30*AH46 -> 6391.703
B46: as % of total revenue | C46: =C45/C30 -> 0.2037373 | D46: =D45/D30 -> 0.18421449 | E46: =E45/E30 -> 0.18044041 | F46: =F45/F30 -> 0.25978168 | G46: =G45/G30 -> 0.15828469 | H46: =H45/H30 -> 0.16909057 | I46: =I45/I30 -> 0.14861617 | J46: =J45/J30 -> 0.15075605 | ... Y46: =Y45/Y30 -> 0.15177758 | Z46: 0.15 | AA46: 0.15 | AB46: 0.15 | AC46: 0.15 | AD46: 0.15 | AE46: 0.15 | AF46: 0.15 | AG46: 0.15 | AH46: 0.15

Sheet IS
B3: (all amounts are in inr millions) | C3: 1QFY21 | D3: 2QFY21 | E3: 3QFY21 | F3: 4QFY21 | G3: 1QFY22 | H3: 2QFY22 | I3: 3QFY22 | J3: 4QFY22 | K3: 1QFY23 | L3: 2QFY23 | M3: 3QFY23 | N3: 4QFY23 | O3: 1QFY24 | P3: 2QFY24 | Q3: 3QFY24 | R3: 4QFY24 | S3: 1QFY25 | T3: 2QFY25 | U3: 3QFY25 | V3: 4QFY25 | W3: 1QFY26 | X3: 2QFY26 | Y3: 3QFY26 | Z3: 4QFY26E | AA3: 1QFY27E | AB3: 2QFY27E | AC3: 3QFY27E | AD3: 4QFY27E | AE3: 1QFY28E | AF3: 2QFY28E | AG3: 3QFY28E | AH3: 4QFY28E | AJ3: FY21 | AK3: FY22 | AL3: FY23 | AM3: FY24 | AN3: FY25 | AO3: FY26E | AP3: FY27E | AQ3: FY28E
B4: Payments | C4: 4064 | D4: 4725 | E4: 5233 | F4: 5786 | G4: 6345 | H4: 7539 | I4: 9916 | J4: 10405 | K4: 10760 | L4: 11730 | M4: 11530 | N4: 14420 | O4: 13960 | P4: 15006 | Q4: 16790 | R4: 15550 | S4: 8840 | T4: 9460 | U4: 10030 | V4: 10460 | W4: 10440 | X4: 11460 | Y4: 11920 | Z4: ='Revenue & Cost'!Z17 -> 12080.912 | AA4: ='Revenue & Cost'!AA17 -> 12694.753 | AB4: ='Revenue & Cost'!AB17 -> 13485.777 | AC4: ='Revenue & Cost'!AC17 -> 14765.245 | AD4: ='Revenue & Cost'!AD17 -> 15038.283 | AE4: ='Revenue & Cost'!AE17 -> 15802.39 | AF4: ='Revenue & Cost'!AF17 -> 16787.055 | AG4: ='Revenue & Cost'!AG17 -> 18379.732 | AH4: ='Revenue & Cost'!AH17 -> 18719.609 | AJ4: =SUM(C4:F4) -> 19808 | AK4: =SUM(G4:J4) -> 34205 | AL4: =SUM(K4:N4) -> 48440 | AM4: =SUM(O4:R4) -> 61306 | AN4: =SUM(S4:V4) -> 38790 | AO4: =SUM(W4:Z4) -> 45900.912 | AP4: =SUM(AA4:AD4) -> 55984.058 | AQ4: =SUM(AE4:AH4) -> 69688.786
B5: Financial services | C5: 234 | D5: 253 | E5: 416 | F5: 381 | G5: 549 | H5: 887 | I5: 1252 | J5: 1684 | K5: 2710 | L5: 3490 | M5: 4460 | N5: 4750 | O5: 5220 | P5: 5710 | Q5: 6070 | R5: 3040 | S5: 2800 | T5: 3760 | U5: 5020 | V5: 5450 | W5: 5605 | X5: 6110 | Y5: 6720 | Z5: ='Revenue & Cost'!Z19 -> 7390.9002 | AA5: ='Revenue & Cost'!AA19 -> 8128.7805 | AB5: ='Revenue & Cost'!AB19 -> 8940.3282 | AC5: ='Revenue & Cost'!AC19 -> 9832.8978 | AD5: ='Revenue & Cost'!AD19 -> 10814.578 | AE5: ='Revenue & Cost'!AE19 -> 11894.266 | AF5: ='Revenue & Cost'!AF19 -> 13081.746 | AG5: ='Revenue & Cost'!AG19 -> 14387.78 | AH5: ='Revenue & Cost'!AH19 -> 15824.203 | AJ5: =SUM(C5:F5) -> 1284 | AK5: =SUM(G5:J5) -> 4372 | AL5: =SUM(K5:N5) -> 15410 | AM5: =SUM(O5:R5) -> 20040 | AN5: =SUM(S5:V5) -> 17030 | AO5: =SUM(W5:Z5) -> 25825.9 | AP5: =SUM(AA5:AD5) -> 37716.585 | AQ5: =SUM(AE5:AH5) -> 55187.994
B6: Marketing Service (cloud and commerce) | C6: 1214 | D6: 1661 | E6: 2071 | F6: 1986 | G6: 2014 | H6: 2438 | I6: 3393 | J6: 3203 | K6: 3329 | L6: 3770 | M6: 4200 | N6: 3930 | O6: 4050 | P6: 4230 | Q6: 5140 | R6: 3950 | S6: 3210 | T6: 3020 | U6: 2670 | V6: 2670 | W6: 2465 | X6: 2280 | Y6: 2380 | Z6: ='Revenue & Cost'!Z23 -> 2484.386 | AA6: ='Revenue & Cost'!AA23 -> 2593.3503 | AB6: ='Revenue & Cost'!AB23 -> 2707.0937 | AC6: ='Revenue & Cost'!AC23 -> 2825.8259 | AD6: ='Revenue & Cost'!AD23 -> 2949.7656 | AE6: ='Revenue & Cost'!AE23 -> 3079.1413 | AF6: ='Revenue & Cost'!AF23 -> 3214.1913 | AG6: ='Revenue & Cost'!AG23 -> 3355.1647 | AH6: ='Revenue & Cost'!AH23 -> 3502.321 | AJ6: =SUM(C6:F6) -> 6932 | AK6: =SUM(G6:J6) -> 11048 | AL6: =SUM(K6:N6) -> 15229 | AM6: =SUM(O6:R6) -> 17370 | AN6: =SUM(S6:V6) -> 11570 | AO6: =SUM(W6:Z6) -> 9609.386 | AP6: =SUM(AA6:AD6) -> 11076.035 | AQ6: =SUM(AE6:AH6) -> 13150.818
B7: Other operating revenues | C7: 0 | D7: 0 | E7: 0 | F7: 0 | G7: 0 | H7: 0 | I7: 0 | J7: 117 | K7: -3 | L7: 150 | M7: 432 | N7: 245 | O7: 186 | P7: 240 | Q7: 505 | R7: 130 | S7: 166 | T7: 355 | U7: 558 | V7: 535 | W7: 665 | X7: 770 | Y7: 920 | Z7: ='Revenue & Cost'!Z27 -> 1099.2208 | AA7: ='Revenue & Cost'!AA27 -> 1313.3547 | AB7: ='Revenue & Cost'!AB27 -> 1569.203 | AC7: ='Revenue & Cost'!AC27 -> 1874.8919 | AD7: ='Revenue & Cost'!AD27 -> 2240.1306 | AE7: ='Revenue & Cost'!AE27 -> 2676.5197 | AF7: ='Revenue & Cost'!AF27 -> 3197.9196 | AG7: ='Revenue & Cost'!AG27 -> 3820.891 | AH7: ='Revenue & Cost'!AH27 -> 4565.2204 | AJ7: =SUM(C7:F7) -> 0 | AK7: =SUM(G7:J7) -> 117 | AL7: =SUM(K7:N7) -> 824 | AM7: =SUM(O7:R7) -> 1061 | AN7: =SUM(S7:V7) -> 1614 | AO7: =SUM(W7:Z7) -> 3454.2208 | AP7: =SUM(AA7:AD7) -> 6997.5802 | AQ7: =SUM(AE7:AH7) -> 14260.551
B8: Total Revenue | C8: =SUM(C4:C7) -> 5512 | D8: =SUM(D4:D7) -> 6639 | E8: =SUM(E4:E7) -> 7720 | F8: =SUM(F4:F7) -> 8153 | G8: =SUM(G4:G7) -> 8908 | H8: =SUM(H4:H7) -> 10864 | I8: =SUM(I4:I7) -> 14561 | J8: =SUM(J4:J7) -> 15409 | ... AH8: =SUM(AH4:AH7) -> 42611.353 | AJ8: =SUM(C8:F8) -> 28024 | AK8: =SUM(G8:J8) -> 49742 | AL8: =SUM(K8:N8) -> 79903 | AM8: =SUM(O8:R8) -> 99777 | AN8: =SUM(S8:V8) -> 69004 | AO8: =SUM(W8:Z8) -> 84790.419 | AP8: =SUM(AA8:AD8) -> 111774.26 | AQ8: =SUM(AE8:AH8) -> 152288.15
B9: Payment processing charges | C9: 3980 | D9: 4924 | E9: 5177 | F9: 5087 | G9: 5265 | H9: 6700 | I9: 7831 | J9: 7742 | K9: 6938 | L9: 7458 | M9: 7378 | N9: 7803 | O9: 7666 | P9: 8167 | Q9: 9822 | R9: 7148 | S9: 5171 | T9: 5168 | U9: 5704 | V9: 5204 | W9: 5809 | X9: 6290 | Y9: 6710 | Z9: ='Revenue & Cost'!Z33 -> 6800.5805 | AA9: ='Revenue & Cost'!AA33 -> 7146.1235 | AB9: ='Revenue & Cost'!AB33 -> 7591.4064 | AC9: ='Revenue & Cost'!AC33 -> 8311.6437 | AD9: ='Revenue & Cost'!AD33 -> 8465.3421 | AE9: ='Revenue & Cost'!AE33 -> 8895.473 | AF9: ='Revenue & Cost'!AF33 -> 9449.7598 | AG9: ='Revenue & Cost'!AG33 -> 10346.309 | AH9: ='Revenue & Cost'!AH33 -> 10537.632 | AJ9: =SUM(C9:F9) -> 19168 | AK9: =SUM(G9:J9) -> 27538 | AL9: =SUM(K9:N9) -> 29577 | AM9: =SUM(O9:R9) -> 32803 | AN9: =SUM(S9:V9) -> 21247 | AO9: =SUM(W9:Z9) -> 25609.58 | AP9: =SUM(AA9:AD9) -> 31514.516 | AQ9: =SUM(AE9:AH9) -> 39229.174
B10: Marketing & promotional expenses | C10: 841 | D10: 1365 | E10: 2118 | F10: 1001 | G10: 1377 | H10: 1857 | I10: 2831 | J10: 2489 | K10: 3181 | L10: 3275 | M10: 2263 | N10: 2045 | O10: 2653 | P10: 2528 | Q10: 2752 | R10: 1287 | S10: 2214 | T10: 1544 | U10: 1409 | V10: 1427 | W10: 998 | X10: 1220 | Y10: 1460 | Z10: ='Revenue & Cost'!Z36 -> 1613.8793 | AA10: ='Revenue & Cost'!AA36 -> 1731.1167 | AB10: ='Revenue & Cost'!AB36 -> 1869.1681 | AC10: ='Revenue & Cost'!AC36 -> 2050.9202 | AD10: ='Revenue & Cost'!AD36 -> 2172.993 | AE10: ='Revenue & Cost'!AE36 -> 2341.6622 | AF10: ='Revenue & Cost'!AF36 -> 2539.6638 | AG10: ='Revenue & Cost'!AG36 -> 2796.0497 | AH10: ='Revenue & Cost'!AH36 -> 2982.7947 | AJ10: =SUM(C10:F10) -> 5325 | AK10: =SUM(G10:J10) -> 8554 | AL10: =SUM(K10:N10) -> 10764 | AM10: =SUM(O10:R10) -> 9220 | AN10: =SUM(S10:V10) -> 6594 | AO10: =SUM(W10:Z10) -> 5291.8793 | AP10: =SUM(AA10:AD10) -> 7824.1981 | AQ10: =SUM(AE10:AH10) -> 10660.17
B11: Employee Benefit Expense | C11: 2138 | D11: 2862 | E11: 3371 | F11: 3478 | G11: 3507 | H11: 3865 | I11: 8313 | J11: 8634 | K11: 9117 | L11: 9441 | M11: 9456 | N11: 9769 | O11: 11061 | P11: 11915 | Q11: 11872 | R11: 11044 | S11: 9525 | T11: 8310 | U11: 7563 | V11: 7483 | W11: 6426 | X11: 6630 | Y11: 7210 | Z11: ='Revenue & Cost'!Z39 -> 6916.6257 | AA11: ='Revenue & Cost'!AA39 -> 7419.0715 | AB11: ='Revenue & Cost'!AB39 -> 8010.7206 | AC11: ='Revenue & Cost'!AC39 -> 8789.6581 | AD11: ='Revenue & Cost'!AD39 -> 9312.8272 | AE11: ='Revenue & Cost'!AE39 -> 10035.695 | AF11: ='Revenue & Cost'!AF39 -> 10884.273 | AG11: ='Revenue & Cost'!AG39 -> 11983.07 | AH11: ='Revenue & Cost'!AH39 -> 12783.406 | AJ11: =SUM(C11:F11) -> 11849 | AK11: =SUM(G11:J11) -> 24319 | AL11: =SUM(K11:N11) -> 37783 | AM11: =SUM(O11:R11) -> 45892 | AN11: =SUM(S11:V11) -> 32881 | AO11: =SUM(W11:Z11) -> 27182.626 | AP11: =SUM(AA11:AD11) -> 33532.277 | AQ11: =SUM(AE11:AH11) -> 45686.445
B12: Software, cloud and data center expenses | C12: 746 | D12: 721 | E12: 951 | F12: 1080 | G12: 1058 | H12: 1129 | I12: 1301 | J12: 1511 | K12: 1622 | L12: 1728 | M12: 1709 | N12: 1880 | O12: 1550 | P12: 1553 | Q12: 1704 | R12: 1623 | S12: 1824 | T12: 1578 | U12: 1536 | V12: 1459 | W12: 1677 | X12: 1330 | Y12: 1670 | Z12: ='Revenue & Cost'!Z42 -> 1844.4335 | AA12: ='Revenue & Cost'!AA42 -> 1978.4191 | AB12: ='Revenue & Cost'!AB42 -> 2136.1922 | AC12: ='Revenue & Cost'!AC42 -> 2343.9088 | AD12: ='Revenue & Cost'!AD42 -> 2483.4206 | AE12: ='Revenue & Cost'!AE42 -> 2676.1854 | AF12: ='Revenue & Cost'!AF42 -> 2902.4729 | AG12: ='Revenue & Cost'!AG42 -> 3195.4854 | AH12: ='Revenue & Cost'!AH42 -> 3408.9083 | AJ12: =SUM(C12:F12) -> 3498 | AK12: =SUM(G12:J12) -> 4999 | AL12: =SUM(K12:N12) -> 6939 | AM12: =SUM(O12:R12) -> 6430 | AN12: =SUM(S12:V12) -> 6397 | AO12: =SUM(W12:Z12) -> 6521.4335 | AP12: =SUM(AA12:AD12) -> 8941.9406 | AQ12: =SUM(AE12:AH12) -> 12183.052
B13: Other expenses | C13: 1123 | D13: 1223 | E13: 1393 | F13: 2118 | G13: 1410 | H13: 1837 | I13: 2164 | J13: 2323 | K13: 2277 | L13: 2616 | M13: 3123 | N13: 3139 | O13: 3413 | P13: 3333 | Q13: 3950 | R13: 3804 | S13: 4204 | T13: 4028 | U13: 4290 | V13: 4428 | W13: 3550 | X13: 3730 | Y13: 3330 | Z13: ='Revenue & Cost'!Z45 -> 3458.3128 | AA13: ='Revenue & Cost'!AA45 -> 3709.5358 | AB13: ='Revenue & Cost'!AB45 -> 4005.3603 | AC13: ='Revenue & Cost'!AC45 -> 4394.8291 | AD13: ='Revenue & Cost'!AD45 -> 4656.4136 | AE13: ='Revenue & Cost'!AE45 -> 5017.8476 | AF13: ='Revenue & Cost'!AF45 -> 5442.1367 | AG13: ='Revenue & Cost'!AG45 -> 5991.5351 | AH13: ='Revenue & Cost'!AH45 -> 6391.703 | AJ13: =SUM(C13:F13) -> 5857 | AK13: =SUM(G13:J13) -> 7734 | AL13: =SUM(K13:N13) -> 11155 | AM13: =SUM(O13:R13) -> 14500 | AN13: =SUM(S13:V13) -> 16950 | AO13: =SUM(W13:Z13) -> 14068.313 | AP13: =SUM(AA13:AD13) -> 16766.139 | AQ13: =SUM(AE13:AH13) -> 22843.222
B14: Total Operating expenses | C14: =SUM(C9:C13) -> 8828 | D14: =SUM(D9:D13) -> 11095 | E14: =SUM(E9:E13) -> 13010 | F14: =SUM(F9:F13) -> 12764 | G14: =SUM(G9:G13) -> 12617 | H14: =SUM(H9:H13) -> 15388 | I14: =SUM(I9:I13) -> 22440 | J14: =SUM(J9:J13) -> 22699 | ... AH14: =SUM(AH9:AH13) -> 36104.444 | AJ14: =SUM(C14:F14) -> 45697 | AK14: =SUM(G14:J14) -> 73144 | AL14: =SUM(K14:N14) -> 96218 | AM14: =SUM(O14:R14) -> 108845 | AN14: =SUM(S14:V14) -> 84069 | AO14: =SUM(W14:Z14) -> 78673.832 | AP14: =SUM(AA14:AD14) -> 98579.071 | AQ14: =SUM(AE14:AH14) -> 130602.06
B15: EBITDA | C15: =C8-C14 -> -3316 | D15: =D8-D14 -> -4456 | E15: =E8-E14 -> -5290 | F15: =F8-F14 -> -4611 | G15: =G8-G14 -> -3709 | H15: =H8-H14 -> -4524 | I15: =I8-I14 -> -7879 | J15: =J8-J14 -> -7290 | ... AH15: =AH8-AH14 -> 6506.909 | AJ15: =SUM(C15:F15) -> -17673 | AK15: =SUM(G15:J15) -> -23402 | AL15: =SUM(K15:N15) -> -16315 | AM15: =SUM(O15:R15) -> -9068 | AN15: =SUM(S15:V15) -> -15065 | AO15: =SUM(W15:Z15) -> 6116.5871 | AP15: =SUM(AA15:AD15) -> 13195.188 | AQ15: =SUM(AE15:AH15) -> 21686.086
B16: Total D&A | C16: 403 | D16: 490 | E16: 382 | F16: 510 | G16: 409 | H16: 504 | I16: 609 | J16: 951 | K16: 972 | L16: 1043 | M16: 1240 | N16: 1598 | O16: 1591 | P16: 1801 | Q16: 2009 | R16: 1956 | S16: 1784 | T16: 1786 | U16: 1653 | V16: 1503 | W16: 1661 | X16: 1370 | Y16: 1330 | Z16: =AO16-SUM(W16:Y16) -> -121.47906 | AA16: =AP16/4 -> 1397.1782 | AB16: =AA16 -> 1397.1782 | AC16: =AB16 -> 1397.1782 | AD16: =AC16 -> 1397.1782 | AE16: =AQ16/4 -> 1903.6019 | AF16: =AE16 -> 1903.6019 | AG16: =AF16 -> 1903.6019 | AH16: =AG16 -> 1903.6019 | AJ16: =SUM(C16:F16) -> 1785 | AK16: =SUM(G16:J16) -> 2473 | AL16: =SUM(K16:N16) -> 4853 | AM16: =SUM(O16:R16) -> 7357 | AN16: =SUM(S16:V16) -> 6726 | AO16: =BS!H68 -> 4239.5209 | AP16: =BS!I68 -> 5588.7129 | AQ16: =BS!J68 -> 7614.4075
B17: EBIT | C17: =C15-C16 -> -3719 | D17: =D15-D16 -> -4946 | E17: =E15-E16 -> -5672 | F17: =F15-F16 -> -5121 | G17: =G15-G16 -> -4118 | H17: =H15-H16 -> -5028 | I17: =I15-I16 -> -8488 | J17: =J15-J16 -> -8241 | ... AH17: =AH15-AH16 -> 4603.3071 | AJ17: =SUM(C17:F17) -> -19458 | AK17: =SUM(G17:J17) -> -25875 | AL17: =SUM(K17:N17) -> -21168 | AM17: =SUM(O17:R17) -> -16425 | AN17: =SUM(S17:V17) -> -21791 | AO17: =SUM(W17:Z17) -> 1877.0661 | AP17: =SUM(AA17:AD17) -> 7606.4746 | AQ17: =SUM(AE17:AH17) -> 14071.678
B18: Finance Cost | C18: -102 | D18: -83 | E18: -92 | F18: -71 | G18: -97 | H18: -102 | I18: -125 | J18: -70 | K18: -55 | L18: -53 | M18: -54 | N18: -71 | O18: -67 | P18: -70 | Q18: -54 | R18: -52 | S18: -42 | T18: -34 | U18: -43 | V18: -45 | W18: -40 | X18: -50 | Y18: -40 | Z18: =Y18 -> -40 | AA18: =Z18 -> -40 | AB18: =AA18 -> -40 | AC18: =AB18 -> -40 | AD18: =AC18 -> -40 | AE18: =AD18 -> -40 | AF18: =AE18 -> -40 | AG18: =AF18 -> -40 | AH18: =AG18 -> -40 | AJ18: =SUM(C18:F18) -> -348 | AK18: =SUM(G18:J18) -> -394 | AL18: =SUM(K18:N18) -> -233 | AM18: =SUM(O18:R18) -> -243 | AN18: =SUM(S18:V18) -> -164 | AO18: =SUM(W18:Z18) -> -170 | AP18: =SUM(AA18:AD18) -> -160 | AQ18: =SUM(AE18:AH18) -> -160
B19: other income | C19: 982 | D19: 942 | E19: 955 | F19: 965 | G19: 572 | H19: 481 | I19: 773 | J19: 1075 | K19: 1020 | L19: 996 | M19: 780 | N19: 1301 | O19: 1226 | P19: 1439 | Q19: 1486 | R19: 1317 | S19: 1375 | T19: 1745 | U19: 1887 | V19: 2238 | W19: 2414 | X19: 2220 | Y19: 2120 | Z19: =Y19 -> 2120 | AA19: =Z19 -> 2120 | AB19: =AA19 -> 2120 | AC19: =AB19 -> 2120 | AD19: =AC19 -> 2120 | AE19: =AD19 -> 2120 | AF19: =AE19 -> 2120 | AG19: =AF19 -> 2120 | AH19: =AG19 -> 2120 | AJ19: =SUM(C19:F19) -> 3844 | AK19: =SUM(G19:J19) -> 2901 | AL19: =SUM(K19:N19) -> 4097 | AM19: =SUM(O19:R19) -> 5468 | AN19: =SUM(S19:V19) -> 7245 | AO19: =SUM(W19:Z19) -> 8874 | AP19: =SUM(AA19:AD19) -> 8480 | AQ19: =SUM(AE19:AH19) -> 8480
B20: share in net profit/loss | C20: 34 | D20: -196 | E20: -243 | F20: -335 | G20: -121 | H20: -66 | I20: 111 | J20: -383 | K20: -60 | L20: -92 | M20: 50 | N20: -23 | O20: -181 | P20: 9 | Q20: -38 | R20: -167 | S20: -13 | T20: 43 | U20: -2 | V20: -3 | W20: 4 | X20: -10 | Y20: -10 | Z20: =Y20 -> -10 | AA20: =Z20 -> -10 | AB20: =AA20 -> -10 | AC20: =AB20 -> -10 | AD20: =AC20 -> -10 | AE20: =AD20 -> -10 | AF20: =AE20 -> -10 | AG20: =AF20 -> -10 | AH20: =AG20 -> -10 | AJ20: =SUM(C20:F20) -> -740 | AK20: =SUM(G20:J20) -> -459 | AL20: =SUM(K20:N20) -> -125 | AM20: =SUM(O20:R20) -> -377 | AN20: =SUM(S20:V20) -> 25 | AO20: =SUM(W20:Z20) -> -26 | AP20: =SUM(AA20:AD20) -> -40 | AQ20: =SUM(AE20:AH20) -> -40
B21: Profit before tax | C21: =C17+SUM(C18:C20) -> -2805 | D21: =D17+SUM(D18:D20) -> -4283 | E21: =E17+SUM(E18:E20) -> -5052 | F21: =F17+SUM(F18:F20) -> -4562 | G21: =G17+SUM(G18:G20) -> -3764 | H21: =H17+SUM(H18:H20) -> -4715 | I21: =I17+SUM(I18:I20) -> -7729 | J21: =J17+SUM(J18:J20) -> -7619 | ... AH21: =AH17+SUM(AH18:AH20) -> 6673.3071 | AJ21: =SUM(C21:F21) -> -16702 | AK21: =SUM(G21:J21) -> -23827 | AL21: =SUM(K21:N21) -> -17429 | AM21: =SUM(O21:R21) -> -11577 | AN21: =SUM(S21:V21) -> -14685 | AO21: =SUM(W21:Z21) -> 10555.066 | AP21: =SUM(AA21:AD21) -> 15886.475 | AQ21: =SUM(AE21:AH21) -> 22351.678
B22: tax expense | C22: 41 | D22: -84 | E22: -103 | F22: 119 | G22: -31 | H22: -20 | I22: -56 | J22: -6 | K22: -48 | L22: -145 | M22: -150 | N22: 7 | O22: -44 | P22: -127 | Q22: -7 | R22: -141 | S22: -15 | T22: -89 | U22: -50 | V22: -26 | W22: -40 | X22: -100 | Y22: -50 | Z22: =-Z21*Z23 -> -1153.2665 | AA22: =-AA21*AA23 -> -854.69841 | AB22: =-AB21*AB23 -> -940.59404 | AC22: =-AC21*AC23 -> -1020.1806 | AD22: =-AD21*AD23 -> -1156.1456 | AE22: =-AE21*AE23 -> -1162.963 | AF22: =-AF21*AF23 -> -1307.2507 | AG22: =-AG21*AG23 -> -1449.379 | AH22: =-AH21*AH23 -> -1668.3268 | AJ22: =SUM(C22:F22) -> -27 | AK22: =SUM(G22:J22) -> -113 | AL22: =SUM(K22:N22) -> -336 | AM22: =SUM(O22:R22) -> -319 | AN22: =SUM(S22:V22) -> -180 | AO22: =SUM(W22:Z22) -> -1343.2665 | AP22: =SUM(AA22:AD22) -> -3971.6187 | AQ22: =SUM(AE22:AH22) -> -5587.9196
B23: Tax rate | C23: =C22/C21 -> -0.014616756 | D23: =D22/D21 -> 0.019612421 | E23: =E22/E21 -> 0.020387965 | F23: =F22/F21 -> -0.02608505 | G23: =G22/G21 -> 0.0082359192 | H23: =H22/H21 -> 0.0042417815 | I23: =I22/I21 -> 0.0072454393 | J23: =J22/J21 -> 0.00078750492 | ... Y23: =Y22/Y21 -> -0.02173913 | Z23: 0.25 | AA23: 0.25 | AB23: 0.25 | AC23: 0.25 | AD23: 0.25 | AE23: 0.25 | AF23: 0.25 | AG23: 0.25 | AH23: 0.25 | AJ23: =AJ22/AJ21 -> 0.0016165729 | AK23: =AK22/AK21 -> 0.004742519 | AL23: =AL22/AL21 -> 0.019278214 | AM23: =AM22/AM21 -> 0.027554634 | AN23: =AN22/AN21 -> 0.012257406 | AO23: =AO22/AO21 -> -0.12726273 | AP23: =AP22/AP21 -> -0.25 | AQ23: =AQ22/AQ21 -> -0.25
B24: Extraordinary Items | C24: -80 | D24: 0 | E24: -200 | F24: -1 | G24: -24 | H24: 0 | I24: 0 | J24: 0 | K24: 0 | L24: 0 | M24: 0 | N24: 0 | O24: 0 | P24: -57 | Q24: 0 | R24: -2271 | S24: 0 | T24: 13454 | U24: 0 | V24: -5221 | W24: -167 | X24: -1900 | Y24: 0 | Z24: 0 | AA24: 0 | AB24: 0 | AC24: 0 | AD24: 0 | AE24: 0 | AF24: 0 | AG24: 0 | AH24: 0 | AJ24: =SUM(C24:F24) -> -281 | AK24: =SUM(G24:J24) -> -24 | AL24: =SUM(K24:N24) -> 0 | AM24: =SUM(O24:R24) -> -2328 | AN24: =SUM(S24:V24) -> 8233 | AO24: =SUM(W24:Z24) -> -2067 | AP24: =SUM(AA24:AD24) -> 0 | AQ24: =SUM(AE24:AH24) -> 0
B25: Net profit before minority interest | C25: =C21+C22+C24 -> -2844 | D25: =D21+D22+D24 -> -4367 | E25: =E21+E22+E24 -> -5355 | F25: =F21+F22+F24 -> -4444 | G25: =G21+G22+G24 -> -3819 | H25: =H21+H22+H24 -> -4735 | I25: =I21+I22+I24 -> -7785 | J25: =J21+J22+J24 -> -7625 | ... AH25: =AH21+AH22+AH24 -> 5004.9803 | AJ25: =SUM(C25:F25) -> -17010 | AK25: =SUM(G25:J25) -> -23964 | AL25: =SUM(K25:N25) -> -17765 | AM25: =SUM(O25:R25) -> -14224 | AN25: =SUM(S25:V25) -> -6632 | AO25: =SUM(W25:Z25) -> 7144.7996 | AP25: =SUM(AA25:AD25) -> 11914.856 | AQ25: =SUM(AE25:AH25) -> 16763.759
B26: minority interest | C26: 25 | D26: -7 | E26: 5 | F26: 26 | G26: 17 | H26: 6 | I26: 1 | J26: 11 | K26: 10 | L26: 4 | M26: 1 | N26: -9 | O26: 14 | P26: 12 | Q26: 19 | R26: 9 | S26: 12 | T26: -17 | U26: 2 | V26: 48 | W26: 0 | X26: 0 | Y26: 0 | Z26: 0 | AA26: 0 | AB26: 0 | AC26: 0 | AD26: 0 | AE26: 0 | AF26: 0 | AG26: 0 | AH26: 0 | AJ26: =SUM(C26:F26) -> 49 | AK26: =SUM(G26:J26) -> 35 | AL26: =SUM(K26:N26) -> 6 | AM26: =SUM(O26:R26) -> 54 | AN26: =SUM(S26:V26) -> 45 | AO26: =SUM(W26:Z26) -> 0 | AP26: =SUM(AA26:AD26) -> 0 | AQ26: =SUM(AE26:AH26) -> 0
B27: Report net profit | C27: =C25+C26 -> -2819 | D27: =D25+D26 -> -4374 | E27: =E25+E26 -> -5350 | F27: =F25+F26 -> -4418 | G27: =G25+G26 -> -3802 | H27: =H25+H26 -> -4729 | I27: =I25+I26 -> -7784 | J27: =J25+J26 -> -7614 | ... AH27: =AH25+AH26 -> 5004.9803 | AJ27: =SUM(C27:F27) -> -16961 | AK27: =SUM(G27:J27) -> -23929 | AL27: =SUM(K27:N27) -> -17759 | AM27: =SUM(O27:R27) -> -14170 | AN27: =SUM(S27:V27) -> -6587 | AO27: =SUM(W27:Z27) -> 7144.7996 | AP27: =SUM(AA27:AD27) -> 11914.856 | AQ27: =SUM(AE27:AH27) -> 16763.759
AJ28: =SUM(C28:F28) -> 0 | AK28: =SUM(G28:J28) -> 0 | AL28: =SUM(K28:N28) -> 0 | AM28: =SUM(O28:R28) -> 0 | AN28: =SUM(S28:V28) -> 0 | AO28: =SUM(W28:Z28) -> 0 | AP28: =SUM(AA28:AD28) -> 0 | AQ28: =SUM(AE28:AH28) -> 0
B29: Shares basic | C29: 601.88706 | D29: 601.90045 | E29: 601.90045 | F29: 602.25029 | G29: 602.9413 | H29: 606.62222 | I29: 628.97133 | J29: 648.41754 | K29: 648.69596 | L29: 648.87189 | M29: 649.12383 | N29: 641.5613 | O29: 633.98345 | P29: 634.27427 | Q29: 634.59629 | R29: 635.11825 | S29: 635.70323 | T29: 636.31603 | U29: 637.01099 | V29: 637.61406 | W29: 638.02083 | X29: 636.36364 | Y29: 639.10136 | Z29: 639.10136 | AA29: 639.10136 | AB29: 639.10136 | AC29: 639.10136 | AD29: 639.10136 | AE29: 639.10136 | AF29: 639.10136 | AG29: 639.10136 | AH29: 639.10136 | AJ29: 639 | AK29: 639 | AL29: 639 | AM29: 639 | AN29: 639 | AO29: 639 | AP29: 639 | AQ29: 639
B30: Shares Diluted | C30: 601.88706 | D30: 601.90045 | E30: 601.90045 | F30: 602.25029 | G30: 602.9413 | H30: 606.62222 | I30: 628.97133 | J30: 648.41754 | K30: 648.69596 | L30: 648.87189 | M30: 649.12383 | N30: 641.5613 | O30: 633.98345 | P30: 634.27427 | Q30: 634.59629 | R30: 635.11825 | S30: 635.70323 | T30: 649.61512 | U30: 637.01099 | V30: 637.61406 | W30: 648.14815 | X30: 656.25 | Y30: 650.28902 | Z30: 650.28902 | AA30: 650.28902 | AB30: 650.28902 | AC30: 650.28902 | AD30: 650.28902 | AE30: 650.28902 | AF30: 650.28902 | AG30: 650.28902 | AH30: 650.28902 | AJ30: 650 | AK30: 650 | AL30: 650 | AM30: 650 | AN30: 650 | AO30: 650 | AP30: 650 | AQ30: 650
AJ31: =SUM(C31:F31) -> 0 | AK31: =SUM(G31:J31) -> 0 | AL31: =SUM(K31:N31) -> 0 | AM31: =SUM(O31:R31) -> 0 | AN31: =SUM(S31:V31) -> 0 | AO31: =SUM(W31:Z31) -> 0 | AP31: =SUM(AA31:AD31) -> 0 | AQ31: =SUM(AE31:AH31) -> 0
B32: EPS Basic | C32: =C27/C29 -> -4.6836029 | D32: =D27/D29 -> -7.2669824 | E32: =E27/E29 -> -8.888513 | F32: =F27/F29 -> -7.3358205 | G32: =G27/G29 -> -6.3057548 | H32: =H27/H29 -> -7.7956261 | I32: =I27/I29 -> -12.375763 | J32: =J27/J29 -> -11.742434 | ... AH32: =AH27/AH29 -> 7.8312779 | AJ32: =SUM(C32:F32) -> -28.174919 | AK32: =SUM(G32:J32) -> -38.219577 | AL32: =SUM(K32:N32) -> -27.398961 | AM32: =SUM(O32:R32) -> -22.3298 | AN32: =SUM(S32:V32) -> -10.343642 | AO32: =SUM(W32:Z32) -> 11.184106 | AP32: =SUM(AA32:AD32) -> 18.64314 | AQ32: =SUM(AE32:AH32) -> 26.230203
B33: EPS Diluted | C33: =C27/C30 -> -4.6836029 | D33: =D27/D30 -> -7.2669824 | E33: =E27/E30 -> -8.888513 | F33: =F27/F30 -> -7.3358205 | G33: =G27/G30 -> -6.3057548 | H33: =H27/H30 -> -7.7956261 | I33: =I27/I30 -> -12.375763 | J33: =J27/J30 -> -11.742434 | ... AH33: =AH27/AH30 -> 7.6965475 | AJ33: =SUM(C33:F33) -> -28.174919 | AK33: =SUM(G33:J33) -> -38.219577 | AL33: =SUM(K33:N33) -> -27.398961 | AM33: =SUM(O33:R33) -> -22.3298 | AN33: =SUM(S33:V33) -> -10.642305 | AO33: =SUM(W33:Z33) -> 10.990403 | AP33: =SUM(AA33:AD33) -> 18.322401 | AQ33: =SUM(AE33:AH33) -> 25.778936

Sheet BS
B2: Balance Sheet
B3: (all amounts are in inr millions) | C3: FY21 | D3: FY22 | E3: FY23 | F3: FY24 | G3: FY25 | H3: FY26E | I3: FY27E | J3: FY28E
B4: Cash and cash equivalents | C4: 5468 | D4: 13790 | E4: 33120 | F4: 42772 | G4: 20769 | H4: =CF!H51 -> 36591.734 | I4: =CF!I51 -> 75189.131 | J4: =CF!J51 -> 120424.71
B5: Other bank balance | C5: 23296 | D5: 38230 | E5: 37275 | F5: 9690 | G5: 94803 | H5: =G5 -> 94803 | I5: =H5 -> 94803 | J5: =I5 -> 94803
B6: Trade receivables | C6: 4713 | D6: 7464 | E6: 12528 | F6: 16507 | G6: 12969 | H6: =IS!AJ8*BS!H61/365 -> 5266.9882 | I6: =IS!AK8*BS!I61/365 -> 9348.7913 | J6: =IS!AL8*BS!J61/365 -> 15017.419
B7: Current investments | C7: 1472 | D7: 0 | E7: 11206 | F7: 23340 | G7: 15908 | H7: =G7 -> 15908 | I7: =H7 -> 15908 | J7: =I7 -> 15908
B8: Loans | C8: 1611 | D8: 514 | E8: 57 | F8: 51 | G8: 1018 | H8: =G8 -> 1018 | I8: =H8 -> 1018 | J8: =I8 -> 1018
B9: Other financial assets | C9: 23386 | D9: 32295 | E9: 33427 | F9: 20564 | G9: 20532 | H9: =G9 -> 20532 | I9: =H9 -> 20532 | J9: =I9 -> 20532
B10: Other current assets | C10: 14052 | D10: 15157 | E10: 12278 | F10: 8713 | G10: 4846 | H10: =G10 -> 4846 | I10: =H10 -> 4846 | J10: =I10 -> 4846
B11: Current assets | C11: =SUM(C4:C10) -> 73998 | D11: =SUM(D4:D10) -> 107450 | E11: =SUM(E4:E10) -> 139891 | F11: =SUM(F4:F10) -> 121637 | G11: =SUM(G4:G10) -> 170845 | H11: =SUM(H4:H10) -> 178965.72 | I11: =SUM(I4:I10) -> 221644.92 | J11: =SUM(J4:J10) -> 272549.13
B13: Property, Plant and Equipment | C13: 2992 | D13: 5616 | E13: 8293 | F13: 9309 | G13: 6454 | H13: =H70 -> 7301.9042 | I13: =I70 -> 8419.6468 | J13: =J70 -> 9942.5283
B14: Intangible assets | C14: 171 | D14: 135 | E14: 469 | F14: 360 | G14: 325 | H14: =G14 -> 325 | I14: =H14 -> 325 | J14: =I14 -> 325
B15: Capital work in progress | C15: 208 | D15: 102 | E15: 72 | F15: 100 | G15: 43 | H15: =G15 -> 43 | I15: =H15 -> 43 | J15: =I15 -> 43
B16: Right of use asset | C16: 1283 | D16: 2945 | E16: 2883 | F16: 2361 | G16: 2117 | H16: =G16 -> 2117 | I16: =H16 -> 2117 | J16: =I16 -> 2117
B17: Goodwill | C17: 467 | D17: 443 | E17: 443 | F17: 443 | G17: 0 | H17: =G17 -> 0 | I17: =H17 -> 0 | J17: =I17 -> 0
B18: Intangible assets under development | C18: 28 | D18: 18 | E18: 42 | F18: 36 | G18: 113 | H18: =G18 -> 113 | I18: =H18 -> 113 | J18: =I18 -> 113
B19: Other financial assets | C19: 3871 | D19: 42131 | E19: 1237 | F19: 3173 | G19: 269 | H19: =G19 -> 269 | I19: =H19 -> 269 | J19: =I19 -> 269
B20: Non-Current Investments | C20: 341 | D20: 10062 | E20: 13247 | F20: 22605 | G20: 25371 | H20: =G20 -> 25371 | I20: =H20 -> 25371 | J20: =I20 -> 25371
B21: Investment in joint ventures | C21: 0 | D21: 0 | E21: 0 | F21: 0 | G21: 0 | H21: =G21 -> 0 | I21: =H21 -> 0 | J21: =I21 -> 0
B22: Investment in associates | C22: 2317 | D22: 2233 | E22: 2518 | F22: 338 | G22: 442 | H22: =G22 -> 442 | I22: =H22 -> 442 | J22: =I22 -> 442
B23: Current tax assets | C23: 3016 | D23: 4317 | E23: 5769 | F23: 6585 | G23: 6125 | H23: =G23 -> 6125 | I23: =H23 -> 6125 | J23: =I23 -> 6125
B24: Deferred tax assets | C24: 35 | D24: 70 | E24: 85 | F24: 119 | G24: 112 | H24: =G24 -> 112 | I24: =H24 -> 112 | J24: =I24 -> 112
B25: Other non-current assets | C25: 2786 | D25: 3032 | E25: 3202 | F25: 2645 | G25: 390 | H25: =G25 -> 390 | I25: =H25 -> 390 | J25: =I25 -> 390
B26: loans | C26: 0 | D26: 1362 | E26: 1507 | F26: 1680 | G26: 1871 | H26: =G26 -> 1871 | I26: =H26 -> 1871 | J26: =I26 -> 1871
B27: Non current assets | C27: =SUM(C13:C26) -> 17515 | D27: =SUM(D13:D26) -> 72466 | E27: =SUM(E13:E26) -> 39767 | F27: =SUM(F13:F26) -> 49754 | G27: =SUM(G13:G26) -> 43632 | H27: =SUM(H13:H26) -> 44479.904 | I27: =SUM(I13:I26) -> 45597.647 | J27: =SUM(J13:J26) -> 47120.528
B28: Total assets | C28: =C27+C11 -> 91513 | D28: =D27+D11 -> 179916 | E28: =E27+E11 -> 179658 | F28: =F27+F11 -> 171391 | G28: =G27+G11 -> 214477 | H28: =H27+H11 -> 223445.63 | I28: =I27+I11 -> 267242.57 | J28: =J27+J11 -> 319669.66
B30: Trade payables | C30: =5996+56 -> 6052 | D30: =7285+229 -> 7514 | E30: =8172+417 -> 8589 | F30: =6529+313 -> 6842 | G30: =7073+336 -> 7409 | H30: =(IS!AJ14-IS!AJ11)*BS!H61/365 -> 6361.5836 | I30: =(IS!AK14-IS!AK11)*BS!I61/365 -> 9176.4452 | J30: =(IS!AL14-IS!AL11)*BS!J61/365 -> 10982.603
B31: Borrowings | C31: 5449 | D31: 1 | E31: 20 | F31: 0 | G31: 48 | H31: =G31 -> 48 | I31: =H31 -> 48 | J31: =I31 -> 48
B32: Lease liabilities | C32: 244 | D32: 392 | E32: 337 | F32: 317 | G32: 342 | H32: 342 | I32: 342 | J32: 342
B33: Other financial liabilities | C33: 5153 | D33: 18005 | E33: 27586 | F33: 19351 | G33: 47842 | H33: 47842 | I33: 47842 | J33: 47842
B34: Other current liabilities | C34: 2643 | D34: 4514 | E34: 4189 | F34: =3207+99 -> 3306 | G34: =2146+5 -> 2151 | H34: =2146+5 -> 2151 | I34: =2146+5 -> 2151 | J34: =2146+5 -> 2151
B35: Contract liabilities | C35: 1581 | D35: 2076 | E35: 2573 | F35: 2624 | G35: 1757 | H35: 1757 | I35: 1757 | J35: 1757
B36: Provisions | C36: 430 | D36: 823 | E36: 1575 | F36: 2713 | G36: 2315 | H36: 2315 | I36: 2315 | J36: 2315
B37: Current liabilities | C37: =SUM(C30:C36) -> 21552 | D37: =SUM(D30:D36) -> 33325 | E37: =SUM(E30:E36) -> 44869 | F37: =SUM(F30:F36) -> 35153 | G37: =SUM(G30:G36) -> 61864 | H37: =SUM(H30:H36) -> 60816.584 | I37: =SUM(I30:I36) -> 63631.445 | J37: =SUM(J30:J36) -> 65437.603
B39: Lease liabilities | C39: 427 | D39: 1822 | E39: 1876 | F39: 1449 | G39: 1214 | H39: =G39 -> 1214 | I39: =H39 -> 1214 | J39: =I39 -> 1214
B40: Provisions | C40: 247 | D40: 307 | E40: 617 | F40: 1081 | G40: 909 | H40: =G40 -> 909 | I40: =H40 -> 909 | J40: =I40 -> 909
B41: Contract liabilities | C41: 4119 | D41: 3165 | E41: 2367 | F41: =518+206 -> 724 | G41: =376+143 -> 519 | H41: =G41 -> 519 | I41: =H41 -> 519 | J41: =I41 -> 519
B42: Deferred tax liabilities | C42: 6 | D42: 2 | E42: 0 | F42: 0 | G42: 0 | H42: =G42 -> 0 | I42: =H42 -> 0 | J42: =I42 -> 0
B43: Total non-current liabilities | C43: =SUM(C39:C42) -> 4799 | D43: =SUM(D39:D42) -> 5296 | E43: =SUM(E39:E42) -> 4860 | F43: =SUM(F39:F42) -> 3254 | G43: =SUM(G39:G42) -> 2642 | H43: =SUM(H39:H42) -> 2642 | I43: =SUM(I39:I42) -> 2642 | J43: =SUM(J39:J42) -> 2642
B44: Total liabilities | C44: =C37+C43 -> 26351 | D44: =D37+D43 -> 38621 | E44: =E37+E43 -> 49729 | F44: =F37+F43 -> 38407 | G44: =G37+G43 -> 64506 | H44: =H37+H43 -> 63458.584 | I44: =I37+I43 -> 66273.445 | J44: =J37+J43 -> 68079.603
...

Sheet CF
B2: Cash Flow Statement
B3: (all amounts are in inr millions) | C3: FY21 | D3: FY22 | E3: FY23 | F3: FY24 | G3: FY25 | H3: FY26E | I3: FY27E | J3: FY28E
B5: Profit before tax | C5: -16983 | D5: -23851 | E5: -17429 | F5: -13904 | G5: -6452 | H5: =IS!AO27 -> 7144.7996 | I5: =IS!AP27 -> 11914.856 | J5: =IS!AQ27 -> 16763.759
B6: Depreciation | C6: 1785 | D6: 2473 | E6: 4853 | F6: 7357 | G6: 6726 | H6: =BS!H68 -> 4239.5209 | I6: =BS!I68 -> 5588.7129 | J6: =BS!J68 -> 7614.4075
B7: Interest income | C7: =-2229-218 -> -2447 | D7: =-2518-92 -> -2610 | E7: =-2778-411 -> -3189 | F7: =+-2637-1916 -> -4553 | G7: =+-2565-2876 -> -5441 | H7: 0 | I7: 0 | J7: 0
B8: Interest cost | C8: =216+123 -> 339 | D8: =294+86 -> 380 | E8: =1+198 -> 199 | F8: 178 | G8: 143 | H8: 0 | I8: 0 | J8: 0
B9: Impairment | C9: =67-30+300+3+0 -> 340 | D9: =391-19+11+24+0 -> 407 | E9: =143-92+17 -> 68 | F9: =122-161+4 -> -35 | G9: =552-220+4 -> 336 | H9: 0 | I9: 0 | J9: 0
B10: Bad debt | C10: =428+19 -> 447 | D10: 432 | E10: 794 | F10: 1160 | G10: 3272 | H10: 0 | I10: 0 | J10: 0
B11: Share- based payment expense | C11: =1125+67-221 -> 971 | D11: 8093 | E11: 14558 | F11: 14658 | G11: 13078 | H11: =G11 -> 13078 | I11: =H11 -> 13078 | J11: =I11 -> 13078
B12: Fair value loss/ (gain) on financial instruments | C12: =-50-899 -> -949 | D12: =-3-215 -> -218 | E12: =15-609 -> -594 | F12: =+-781 -> -781 | G12: -1360 | H12: 0 | I12: 0 | J12: 0
B13: Other income | C13: =C14-SUM(C5:C12) -> 703 | D13: =D14-SUM(D5:D12) -> 529 | E13: =E14-SUM(E5:E12) -> 169 | F13: =F14-SUM(F5:F12) -> 3662 | G13: =G14-SUM(G5:G12) -> -10366 | H13: 0 | I13: 0 | J13: 0
B14: Operating loss before working capital changes | C14: -15794 | D14: -14365 | E14: -571 | F14: 7742 | G14: -64 | H14: =SUM(H5:H13) -> 24462.321 | I14: =SUM(I5:I13) -> 30581.569 | J14: =SUM(J5:J13) -> 37456.166
B15: (Increase)/decrease in working capital: | C15: =SUM(C16:C23) -> -6902 | D15: =SUM(D16:D23) -> 3481 | E15: =SUM(E16:E23) -> 6489 | F15: =SUM(F16:F23) -> -149 | G15: =SUM(G16:G23) -> -1329 | H15: =SUM(H16:H23) -> -8749.4282 | I15: =SUM(I16:I23) -> 6896.6648 | J15: =SUM(J16:J23) -> 7474.7855
B16: Trade Payables | C16: -33 | D16: 1481 | E16: 1090 | F16: -1837 | G16: 992 | H16: =BS!H30-BS!G30 -> -1047.4164 | I16: =BS!I30-BS!H30 -> 2814.8616 | J16: =BS!J30-BS!I30 -> 1806.1575
B17: Provisions | C17: -85 | D17: 434 | E17: 981 | F17: 1547 | G17: -382 | H17: =BS!H40-BS!G40 -> 0 | I17: =BS!I40-BS!H40 -> 0 | J17: =BS!J40-BS!I40 -> 0
B18: Other liabilities | C18: -273 | D18: 1412 | E18: -626 | F18: -2529 | G18: -2128 | H18: =BS!H32-BS!G32+BS!H34-BS!G34+BS!H35-BS!G35 -> 0 | I18: =BS!I32-BS!H32+BS!I34-BS!H34+BS!I35-BS!H35 -> 0 | J18: =BS!J32-BS!I32+BS!J34-BS!I34+BS!J35-BS!I35 -> 0
B19: Other financial liabilities | C19: 2669 | D19: 13338 | E19: 9415 | F19: -7888 | G19: =9781-9133 -> 648 | H19: =BS!H33-BS!G33 -> 0 | I19: =BS!I33-BS!H33 -> 0 | J19: =BS!J33-BS!I33 -> 0
B20: Trade receivables | C20: -67 | D20: -3192 | E20: -5539 | F20: -5058 | G20: -262 | H20: =BS!H6-BS!G6 -> -7702.0118 | I20: =BS!I6-BS!H6 -> 4081.8031 | J20: =BS!J6-BS!I6 -> 5668.628
B21: Other financial assets | C21: -6384 | D21: -9187 | E21: -1267 | F21: 12355 | G21: -395 | H21: =BS!H9-BS!G9 -> 0 | I21: =BS!I9-BS!H9 -> 0 | J21: =BS!J9-BS!I9 -> 0
B22: Other assets | C22: -2729 | D22: -805 | E22: 2435 | F22: 3261 | G22: 1125 | H22: =BS!H5-BS!G5+BS!H7-BS!G7+BS!H10-BS!G10 -> 0 | I22: =BS!I5-BS!H5+BS!I7-BS!H7+BS!I10-BS!H10 -> 0 | J22: =BS!J5-BS!I5+BS!J7-BS!I7+BS!J10-BS!I10 -> 0
B23: Loans | C23: 0 | D23: 0 | E23: 0 | F23: 0 | G23: -927 | H23: =BS!H26-BS!G26 -> 0 | I23: =BS!I26-BS!H26 -> 0 | J23: =BS!J26-BS!I26 -> 0
B24: Income tax paid | C24: 1871 | D24: -1479 | E24: -1762 | F24: -1085 | G24: 180 | H24: =-IS!AO22 -> 1343.2665 | I24: =-IS!AP22 -> 3971.6187 | J24: =-IS!AQ22 -> 5587.9196
B25: Cash flow from operations | C25: =C14+C15+C24 -> -20825 | D25: =D14+D15+D24 -> -12363 | E25: =E14+E15+E24 -> 4156 | F25: =F14+F15+F24 -> 6508 | G25: =G14+G15+G24 -> -1213 | H25: =H14+H15+H24 -> 17056.159 | I25: =I14+I15+I24 -> 41449.852 | J25: =J14+J15+J24 -> 50518.871
B27: Capital expenditure | C27: -1927 | D27: -5071 | E27: -7052 | F27: -8217 | G27: -3219 | H27: =-BS!H66 -> -5087.4251 | I27: =-BS!I66 -> -6706.4555 | J27: =-BS!J66 -> -9137.289
B28: (Acquisitions)/divestitures | C28: 0 | D28: 0 | E28: 0 | F28: 0 | G28: 0 | H28: 0 | I28: 0 | J28: 0
B29: Change in Intangibles | H29: 0 | I29: 0 | J29: 0
B30: Investments (net) | C30: =-21534+10419+5-1608-87+1036+99456-67468 -> 20219 | D30: =-96322+43206+908-1653+13-261+85696-84204 -> -52617 | E30: =-57876+99248+483-10-1226+351192-361669 -> 30142 | F30: =+-35101+60435+10+0-8199+233544-244992 -> 5697 | G30: =+-71846+13882+20036+26689-23767+562305-548880 -> -21581 | H30: 0 | I30: 0 | J30: 0
B31: Interest received | C31: 950 | D31: 2775 | E31: 3080 | F31: 4727 | G31: 4318 | H31: 4318 | I31: 4318 | J31: 4318
B32: Other investment cash flow items | C32: =C33-SUM(C27:C31) -> 56 | D32: =D33-SUM(D27:D31) -> 27 | E32: =E33-SUM(E27:E31) -> 85 | F32: =F33-SUM(F27:F31) -> 973 | G32: =G33-SUM(G27:G31) -> 53 | H32: 0 | I32: 0 | J32: 0
B33: Cash flow from investing | C33: 19298 | D33: -54886 | E33: 26255 | F33: 3180 | G33: -20429 | H33: =SUM(H27:H32) -> -769.42513 | I33: =SUM(I27:I32) -> -2388.4555 | J33: =SUM(J27:J32) -> -4819.289
B35: Proceeds from issue of shares | C35: 107 | D35: 83067 | E35: 7 | F35: 13 | G35: 13 | H35: 0 | I35: 0 | J35: 0
B36: Share issue expenses | C36: 0 | D36: -1401 | E36: 0 | F36: 0 | G36: 0 | H36: 0 | I36: 0 | J36: 0
B37: Share application money received during the year | C37: 2 | D37: 0 | H37: 0 | I37: 0 | J37: 0
B38: Acquisition of non controlling interests | C38: -63 | D38: 0 | E38: 0 | F38: 0 | G38: 0 | H38: 0 | I38: 0 | J38: 0
B39: Repayment of borrowings on acquisition of subsidiaries | C39: 0 | D39: 0 | E39: 0 | F39: 0 | G39: 0 | H39: 0 | I39: 0 | J39: 0
B40: Repayment of term loan | C40: -729 | D40: 0 | E40: 0 | F40: 0 | G40: 0 | H40: 0 | I40: 0 | J40: 0
B41: Repayment of other borrowings | C41: -6 | D41: 0 | E41: 0 | F41: 0 | G41: 0 | H41: 0 | I41: 0 | J41: 0
B42: Net change in working capital demand loan | C42: -847 | D42: -435 | E42: 0 | F42: 0 | G42: 0 | H42: 0 | I42: 0 | J42: 0
B43: Interest paid | C43: -339 | D43: -380 | E43: -199 | F43: -179 | G43: -146 | H43: =G43 -> -146 | I43: =H43 -> -146 | J43: =I43 -> -146
B44: Proceeds from loan | C44: 0 | D44: 0 | E44: 0 | F44: 0 | G44: 0 | H44: =G44 -> 0 | I44: =H44 -> 0 | J44: =I44 -> 0
...

Sheet DCF
C3: FCF | D3: FY21 | E3: FY22 | F3: FY23 | G3: FY24 | H3: FY25 | I3: FY26E | J3: FY27E | K3: FY28E
C4: EBIT | D4: =IS!AJ17 -> -19458 | E4: =IS!AK17 -> -25875 | F4: =IS!AL17 -> -21168 | G4: =IS!AM17 -> -16425 | H4: =IS!AN17 -> -21791 | I4: =IS!AO17 -> 1877.0661 | J4: =IS!AP17 -> 7606.4746 | K4: =IS!AQ17 -> 14071.678
C5: EBIT x(1- tax rate)) | D5: =D4*(1-IS!AJ23) -> -19426.545 | E5: =E4*(1-IS!AK23) -> -25752.287 | F5: =F4*(1-IS!AL23) -> -20759.919 | G5: =G4*(1-IS!AM23) -> -15972.415 | H5: =H4*(1-IS!AN23) -> -21523.899 | I5: =I4*(1-IS!AO23) -> 2115.9467 | J5: =J4*(1-IS!AP23) -> 9508.0933 | K5: =K4*(1-IS!AQ23) -> 17589.598
C6: + Depreciation and amortization | D6: =IS!AJ16 -> 1785 | E6: =IS!AK16 -> 2473 | F6: =IS!AL16 -> 4853 | G6: =IS!AM16 -> 7357 | H6: =IS!AN16 -> 6726 | I6: =IS!AO16 -> 4239.5209 | J6: =IS!AP16 -> 5588.7129 | K6: =IS!AQ16 -> 7614.4075
C7: - (Increase)/decrease in net WC | D7: =CF!C15 -> -6902 | E7: =CF!D15 -> 3481 | F7: =CF!E15 -> 6489 | G7: =CF!F15 -> -149 | H7: =CF!G15 -> -1329 | I7: =CF!H15 -> -8749.4282 | J7: =CF!I15 -> 6896.6648 | K7: =CF!J15 -> 7474.7855
C8: - (Capital expenditure) | D8: =CF!C27 -> -1927 | E8: =CF!D27 -> -5071 | F8: =CF!E27 -> -7052 | G8: =CF!F27 -> -8217 | H8: =CF!G27 -> -3219 | I8: =CF!H27 -> -5087.4251 | J8: =CF!I27 -> -6706.4555 | K8: =CF!J27 -> -9137.289
C9: FCF (Rs mn) | D9: =SUM(D5:D8) -> -26470.545 | E9: =SUM(E5:E8) -> -24869.287 | F9: =SUM(F5:F8) -> -16469.919 | G9: =SUM(G5:G8) -> -16981.415 | H9: =SUM(H5:H8) -> -19345.899 | I9: =SUM(I5:I8) -> -7481.3857 | J9: =SUM(J5:J8) -> 15287.015 | K9: =SUM(K5:K8) -> 23541.502
C10: % growth
C11: Discounting factor | I11: =(1/((1+$F$33)^1)) -> 0.89485459 | J11: =(1/((1+$F$33)^2)) -> 0.80076473 | K11: =(1/((1+$F$33)^3)) -> 0.71656799
C12: PV of FCF | I12: =I9*I11 -> -6694.7523 | J12: =J9*J11 -> 12241.303 | K12: =K9*K11 -> 16869.087
C13: Terminal Value | K13: =(K12*(1+F34))/(F33-F34) -> 310977.95
C15: DCF
C16: Enterprise value | D16: =SUM(I12:K12)+K13 -> 333393.58
C17: Net debt | D17: =BS!G56 -> -129876
C18: minority interest | D18: =BS!G50 -> -296
C19: Equity value | D19: =D16-D17-D18 -> 463565.58
C20: shares outstanding (Mn) | D20: 639
C21: Equity value/ share | D21: =D19/D20 -> 725.45475 | E21: >>> Overvalued
C23: Current share price of paytm | D23: 1148
C26: WACC
C27: India risk free rate | D27: % | F27: 0.065
C28: Equity risk premium | D28: % | F28: 0.05
C29: Beta | D29: x | F29: 1.05
C30: Cost of Equity | D30: % | F30: =+F27+F28*F29 -> 0.1175
C32: Target debt to Equity | D32: % | F32: 0
C33: WACC | D33: % | F33: =+F30*(1-F32)+F31*F32 -> 0.1175
C34: Terminal growth rate | D34: % | F34: 0.06
